Workbook

Sheet 사용안내
B2: ㈜신정개발 급여관리 (샘플·가상데이터)
B3: 급여 대시보드 웹서비스(GitHub → Vercel)의 데이터 원본입니다. 시트/열 구조는 유지하고 파란색 셀의 값만 수정하세요.
B5: ■ 시트 구성
B6: 1. 요율기준 : 4대보험 요율·국민연금 상하한·소정근로시간(209h)·연장/야간 가산율·식대/차량 비과세한도. 기준값 변경 시 이 시트만 고치면 전체 재계산.
B7: 2. 직원정보 : 직원 마스터. 부양가족수(본인 포함, 파란색)는 갑근세 계산에 반영.
B8: 3. 급여대장 : ★ 직원별 연간(1~12월, 38명×12개월=456행) 급여대장. 상단 필터(▼)에서 성명을 선택하면 그 직원의 1년 지급내역과 합계(2행)가 나옵니다.
B9: 4. 4대보험 : 국민연금·건강·장기요양·고용·산재 — 근로자/회사 부담을 나눠 자동계산. 성명 필터 가능.
B10: 5. 세금 : 근로소득 간이세액 산식으로 갑근세·지방소득세 자동계산. 성명 필터 가능.
B11: 6. 급여명세서 : F4에 직원 NO, F5에 월(月)을 입력하면 해당 월 발송용 명세서가 자동 완성.
B13: ■ 시간급여(통상시급) 계산
B14: · 통상시급 = 기본급 ÷ 월 소정근로시간(209h) → 연장·야간 근로시간(파란색)만 입력하면 수당이 자동 산출됩니다.
B15: · 연장근로수당 = 통상시급 × 1.5 × 연장시간 / 야간근로수당 = 통상시급 × 0.5 × 야간시간(가산분)
... B27: · 급여 금액은 직급별 예시값입니다. 실제 값으로 교체하세요. 주민번호·연락처 등 개인정보는 공개 저장소 노출에 주의하세요.

Sheet 요율기준
A1: 급여 계산 기준값 (2026년 귀속)
A3: 항목 | B3: 값 | C3: 비고 / 출처
A4: 국민연금 요율(근로자부담) | B4: 0.045 | C4: 기준소득월액×4.5% (회사 4.5% 별도) — 국민연금공단
A5: 국민연금 기준소득월액 상한 | B5: 6370000 | C5: 2025.7~2026.6 적용. 매년 7월 변경 — 국민연금공단
A6: 국민연금 기준소득월액 하한 | B6: 400000 | C6: 2025.7~2026.6 적용 — 국민연금공단
A7: 건강보험 요율(근로자부담) | B7: 0.03545 | C7: 보수월액×3.545% (회사 동일) — 2025년 요율
A8: 장기요양보험 요율 | B8: 0.1295 | C8: 건강보험료×12.95% — 국민건강보험공단
A9: 고용보험 요율(근로자부담) | B9: 0.009 | C9: 실업급여분 0.9% — 고용노동부
A10: 고용보험 요율(회사부담) | B10: 0.0115 | C10: 실업급여 0.9%+고용안정·능력개발 0.25%(150인 미만)
A11: 산재보험 요율(회사 전액) | B11: 0.0147 | C11: 예시값. 사업장별 상이 — 근로복지공단 통지요율로 수정
A12: 지방소득세율 | B12: 0.1 | C12: 소득세의 10% — 지방세법
A13: 인적공제(1인당·연간) | B13: 1500000 | C13: 소득세법 기본공제 150만원
A14: 월 소정근로시간 | B14: 209 | C14: 주40시간제 기준 통상임금 산정 시간(주휴 포함)
A15: 연장근로 가산율 | B15: 1.5 | C15: 근로기준법 통상임금 50% 가산
... A18: 차량유지비 비과세 한도(월) | B18: 200000 | C18: 자가운전보조금 월 20만원 비과세

Sheet 직원정보
A1: ㈜신정개발 직원 마스터
A2: ※ 부양가족수(본인 포함, 파란색)는 갑근세 계산에 사용됩니다. 입·퇴사 시 이 시트를 먼저 수정하세요.
A4: NO | B4: 사번 | C4: 성명 | D4: 부서 | E4: 직급 | F4: 주민번호(마스킹) | G4: 연락처 | H4: 입사일 | I4: 부양가족수 (본인포함) | J4: 재직상태 | K4: 비고
A5: 1 | B5: S0001 | C5: 가온누리 | D5: 대표이사실 | E5: 대표이사 | F5: 900101-1****** | G5: 010-0000-1001 | H5: 40239 | I5: 1 | J5: 재직
A6: 2 | B6: S0002 | C6: 나래솔 | D6: 대표이사실 | E6: 이사 | F6: 880202-2****** | G6: 010-0000-1002 | H6: 40673 | I6: 1 | J6: 재직
A7: 3 | B7: S0003 | C7: 다올찬 | D7: 경영지원팀 | E7: 이사 | F7: 850303-1****** | G7: 010-0000-1003 | H7: 40923 | I7: 1 | J7: 재직 | K7: 자격수당 대상
A8: 4 | B8: S0004 | C8: 라온제 | D8: 경영지원팀 | E8: 과장 | F8: 900404-2****** | G8: 010-0000-1004 | H8: 42461 | I8: 1 | J8: 재직
A9: 5 | B9: S0005 | C9: 마루한 | D9: C&M 1팀 | E9: 부장 | F9: 830505-1****** | G9: 010-0000-1005 | H9: 41475 | I9: 1 | J9: 재직 | K9: 자격수당 대상
A10: 6 | B10: S0006 | C10: 바다별 | D10: C&S 1팀 | E10: 부장 | F10: 840606-1****** | G10: 010-0000-1006 | H10: 41681 | I10: 1 | J10: 재직 | K10: 자격수당 대상
A11: 7 | B11: S0007 | C11: 사랑비 | D11: C&S 2팀 | E11: 차장 | F11: 870707-1****** | G11: 010-0000-1007 | H11: 42248 | I11: 1 | J11: 재직
A12: 8 | B12: S0008 | C12: 아름찬 | D12: SAP팀 | E12: 차장 | F12: 860808-1****** | G12: 010-0000-1008 | H12: 42432 | I12: 1 | J12: 재직
A13: 9 | B13: S0009 | C13: 자유롬 | D13: C&M 1팀 | E13: 과장 | F13: 890909-1****** | G13: 010-0000-1009 | H13: 42891 | I13: 1 | J13: 재직 | K13: 자격수당 대상
A14: 10 | B14: S0010 | C14: 차분해 | D14: SAP팀 | E14: 과장 | F14: 911010-1****** | G14: 010-0000-1010 | H14: 43353 | I14: 1 | J14: 재직
A15: 11 | B15: S0011 | C15: 카랑찬 | D15: C&S 1팀 | E15: 대리 | F15: 921111-1****** | G15: 010-0000-1011 | H15: 43790 | I15: 1 | J15: 재직
A16: 12 | B16: S0012 | C16: 타래솔 | D16: C&R팀 | E16: 반장 | F16: 811212-1****** | G16: 010-0000-1012 | H16: 43838 | I16: 1 | J16: 재직 | K16: 자격수당 대상
A17: 13 | B17: S0013 | C17: 파도한 | D17: C&S 2팀 | E17: 사원 | F17: 930113-1****** | G17: 010-0000-1013 | H17: 44268 | I17: 1 | J17: 재직
A18: 14 | B18: S0014 | C18: 하나로 | D18: 안전/공무 | E18: 사원 | F18: 940214-1****** | G18: 010-0000-1014 | H18: 44792 | I18: 1 | J18: 재직
A19: 15 | B19: S0015 | C19: 한결이 | D19: 공사사업부 | E19: 기사 | F19: 900315-1****** | G19: 010-0000-1015 | H19: 42144 | I19: 1 | J19: 재직 | K19: 자격수당 대상
A20: 16 | B20: S0016 | C20: 슬기론 | D20: 공사사업부 | E20: 기사 | F20: 950416-2****** | G20: 010-0000-1016 | H20: 45035 | I20: 1 | J20: 재직 | K20: 자격수당 대상
A21: 17 | B21: S0017 | C21: 빛나라 | D21: 기업부설연구소 | E21: 연구원 | F21: 960517-2****** | G21: 010-0000-1017 | H21: 45332 | I21: 1 | J21: 재직
A22: 18 | B22: S0018 | C22: 온새미 | D22: 현장지원 | E22: 사원 | F22: 970618-1****** | G22: 010-0000-1018 | H22: 45670 | I22: 1 | J22: 재직

Sheet 급여대장
A1: ㈜신정개발 급여대장 (2026년 연간) — 성명 필터 시 해당 직원 1년치 표시
A2: ▼ 상단 필터에서 성명 선택 → 합계 자동반영 → | G2: =SUBTOTAL(109,G5:G220) -> 807600000 | H2: =SUBTOTAL(109,H5:H220) -> 3864096 | I2: =SUBTOTAL(109,I5:I220) -> 3204 | J2: =SUBTOTAL(109,J5:J220) -> 858 | K2: =SUBTOTAL(109,K5:K220) -> 50040000 | L2: =SUBTOTAL(109,L5:L220) -> 78737661 | M2: =SUBTOTAL(109,M5:M220) -> 6967476 | N2: =SUBTOTAL(109,N5:N220) -> 26400000 | ... AE2: =SUBTOTAL(109,AE5:AE220) -> 931245747
A3: 직원 정보 | G3: 지 급 내 역 | T3: 합계 / 과세 | W3: 공 제 내 역 | AE3: 실지급액
A4: 귀속월 | B4: NO | C4: 사번 | D4: 성명 | E4: 부서 | F4: 직급 | G4: 기본급 | H4: 통상시급 | I4: 연장 시간 | J4: 야간 시간 | K4: 약정근로 수당 | L4: 연장근로 수당 | M4: 야간근로 수당 | N4: 직책수당 | O4: 출근수당 | P4: 자격수당 | Q4: 통신비 (비과세) | R4: 식대 (비과세) | S4: 차량유지비 (비과세) | T4: 지급합계 | U4: 비과세 합계 | V4: 과세급여 | W4: 국민연금 | X4: 건강보험 | Y4: 장기요양 | Z4: 고용보험 | AA4: 소득세 | AB4: 지방 소득세 | AC4: 기타공제 | AD4: 공제합계 | AE4: 실지급액
A5: 46023 | B5: 1 | C5: =직원정보!B5 -> S0001 | D5: =직원정보!C5 -> 가온누리 | E5: =직원정보!D5 -> 대표이사실 | F5: =직원정보!E5 -> 대표이사 | G5: 6500000 | H5: =ROUND(G5/요율기준!$B$14,0) -> 31100 | I5: 0 | J5: 0 | K5: 0 | L5: =ROUND(H5*요율기준!$B$15*I5,0) -> 0 | M5: =ROUND(H5*요율기준!$B$16*J5,0) -> 0 | N5: 500000 | O5: 100000 | P5: 0 | Q5: 100000 | R5: 200000 | S5: 200000 | T5: =G5+K5+L5+M5+N5+O5+P5+Q5+R5+S5 -> 7600000 | U5: =Q5+MIN(R5,요율기준!$B$17)+MIN(S5,요율기준!$B$18) -> 500000 | V5: =T5-U5 -> 7100000 | W5: ='4대보험'!F5 -> 286650 | X5: ='4대보험'!H5 -> 251690 | Y5: ='4대보험'!J5 -> 32590 | Z5: ='4대보험'!L5 -> 63900 | AA5: =세금!P5 -> 673170 | AB5: =세금!Q5 -> 67310 | AC5: 0 | AD5: =SUM(W5:AC5) -> 1375310 | AE5: =T5-AD5 -> 6224690
A6: 46054 | B6: 1 | C6: =직원정보!B5 -> S0001 | D6: =직원정보!C5 -> 가온누리 | E6: =직원정보!D5 -> 대표이사실 | F6: =직원정보!E5 -> 대표이사 | G6: 6500000 | H6: =ROUND(G6/요율기준!$B$14,0) -> 31100 | I6: 4 | J6: 0 | K6: 0 | L6: =ROUND(H6*요율기준!$B$15*I6,0) -> 186600 | M6: =ROUND(H6*요율기준!$B$16*J6,0) -> 0 | N6: 500000 | O6: 100000 | P6: 0 | Q6: 100000 | R6: 200000 | S6: 200000 | T6: =G6+K6+L6+M6+N6+O6+P6+Q6+R6+S6 -> 7786600 | U6: =Q6+MIN(R6,요율기준!$B$17)+MIN(S6,요율기준!$B$18) -> 500000 | V6: =T6-U6 -> 7286600 | W6: ='4대보험'!F6 -> 286650 | X6: ='4대보험'!H6 -> 258300 | Y6: ='4대보험'!J6 -> 33440 | Z6: ='4대보험'!L6 -> 65570 | AA6: =세금!P6 -> 713930 | AB6: =세금!Q6 -> 71390 | AC6: 0 | AD6: =SUM(W6:AC6) -> 1429280 | AE6: =T6-AD6 -> 6357320
A7: 46082 | B7: 1 | C7: =직원정보!B5 -> S0001 | D7: =직원정보!C5 -> 가온누리 | E7: =직원정보!D5 -> 대표이사실 | F7: =직원정보!E5 -> 대표이사 | G7: 6500000 | H7: =ROUND(G7/요율기준!$B$14,0) -> 31100 | I7: 0 | J7: 0 | K7: 0 | L7: =ROUND(H7*요율기준!$B$15*I7,0) -> 0 | M7: =ROUND(H7*요율기준!$B$16*J7,0) -> 0 | N7: 500000 | O7: 100000 | P7: 0 | Q7: 100000 | R7: 200000 | S7: 200000 | T7: =G7+K7+L7+M7+N7+O7+P7+Q7+R7+S7 -> 7600000 | U7: =Q7+MIN(R7,요율기준!$B$17)+MIN(S7,요율기준!$B$18) -> 500000 | V7: =T7-U7 -> 7100000 | W7: ='4대보험'!F7 -> 286650 | X7: ='4대보험'!H7 -> 251690 | Y7: ='4대보험'!J7 -> 32590 | Z7: ='4대보험'!L7 -> 63900 | AA7: =세금!P7 -> 673170 | AB7: =세금!Q7 -> 67310 | AC7: 0 | AD7: =SUM(W7:AC7) -> 1375310 | AE7: =T7-AD7 -> 6224690
A8: 46113 | B8: 1 | C8: =직원정보!B5 -> S0001 | D8: =직원정보!C5 -> 가온누리 | E8: =직원정보!D5 -> 대표이사실 | F8: =직원정보!E5 -> 대표이사 | G8: 6500000 | H8: =ROUND(G8/요율기준!$B$14,0) -> 31100 | I8: 4 | J8: 0 | K8: 0 | L8: =ROUND(H8*요율기준!$B$15*I8,0) -> 186600 | M8: =ROUND(H8*요율기준!$B$16*J8,0) -> 0 | N8: 500000 | O8: 100000 | P8: 0 | Q8: 100000 | R8: 200000 | S8: 200000 | T8: =G8+K8+L8+M8+N8+O8+P8+Q8+R8+S8 -> 7786600 | U8: =Q8+MIN(R8,요율기준!$B$17)+MIN(S8,요율기준!$B$18) -> 500000 | V8: =T8-U8 -> 7286600 | W8: ='4대보험'!F8 -> 286650 | X8: ='4대보험'!H8 -> 258300 | Y8: ='4대보험'!J8 -> 33440 | Z8: ='4대보험'!L8 -> 65570 | AA8: =세금!P8 -> 713930 | AB8: =세금!Q8 -> 71390 | AC8: 0 | AD8: =SUM(W8:AC8) -> 1429280 | AE8: =T8-AD8 -> 6357320
A9: 46143 | B9: 1 | C9: =직원정보!B5 -> S0001 | D9: =직원정보!C5 -> 가온누리 | E9: =직원정보!D5 -> 대표이사실 | F9: =직원정보!E5 -> 대표이사 | G9: 6500000 | H9: =ROUND(G9/요율기준!$B$14,0) -> 31100 | I9: 0 | J9: 0 | K9: 0 | L9: =ROUND(H9*요율기준!$B$15*I9,0) -> 0 | M9: =ROUND(H9*요율기준!$B$16*J9,0) -> 0 | N9: 500000 | O9: 100000 | P9: 0 | Q9: 100000 | R9: 200000 | S9: 200000 | T9: =G9+K9+L9+M9+N9+O9+P9+Q9+R9+S9 -> 7600000 | U9: =Q9+MIN(R9,요율기준!$B$17)+MIN(S9,요율기준!$B$18) -> 500000 | V9: =T9-U9 -> 7100000 | W9: ='4대보험'!F9 -> 286650 | X9: ='4대보험'!H9 -> 251690 | Y9: ='4대보험'!J9 -> 32590 | Z9: ='4대보험'!L9 -> 63900 | AA9: =세금!P9 -> 673170 | AB9: =세금!Q9 -> 67310 | AC9: 0 | AD9: =SUM(W9:AC9) -> 1375310 | AE9: =T9-AD9 -> 6224690
A10: 46174 | B10: 1 | C10: =직원정보!B5 -> S0001 | D10: =직원정보!C5 -> 가온누리 | E10: =직원정보!D5 -> 대표이사실 | F10: =직원정보!E5 -> 대표이사 | G10: 6500000 | H10: =ROUND(G10/요율기준!$B$14,0) -> 31100 | I10: 4 | J10: 0 | K10: 0 | L10: =ROUND(H10*요율기준!$B$15*I10,0) -> 186600 | M10: =ROUND(H10*요율기준!$B$16*J10,0) -> 0 | N10: 500000 | O10: 100000 | P10: 0 | Q10: 100000 | R10: 200000 | S10: 200000 | T10: =G10+K10+L10+M10+N10+O10+P10+Q10+R10+S10 -> 7786600 | U10: =Q10+MIN(R10,요율기준!$B$17)+MIN(S10,요율기준!$B$18) -> 500000 | V10: =T10-U10 -> 7286600 | W10: ='4대보험'!F10 -> 286650 | X10: ='4대보험'!H10 -> 258300 | Y10: ='4대보험'!J10 -> 33440 | Z10: ='4대보험'!L10 -> 65570 | AA10: =세금!P10 -> 713930 | AB10: =세금!Q10 -> 71390 | AC10: 0 | AD10: =SUM(W10:AC10) -> 1429280 | AE10: =T10-AD10 -> 6357320
A11: 46204 | B11: 1 | C11: =직원정보!B5 -> S0001 | D11: =직원정보!C5 -> 가온누리 | E11: =직원정보!D5 -> 대표이사실 | F11: =직원정보!E5 -> 대표이사 | G11: 6500000 | H11: =ROUND(G11/요율기준!$B$14,0) -> 31100 | I11: 0 | J11: 0 | K11: 0 | L11: =ROUND(H11*요율기준!$B$15*I11,0) -> 0 | M11: =ROUND(H11*요율기준!$B$16*J11,0) -> 0 | N11: 500000 | O11: 100000 | P11: 0 | Q11: 100000 | R11: 200000 | S11: 200000 | T11: =G11+K11+L11+M11+N11+O11+P11+Q11+R11+S11 -> 7600000 | U11: =Q11+MIN(R11,요율기준!$B$17)+MIN(S11,요율기준!$B$18) -> 500000 | V11: =T11-U11 -> 7100000 | W11: ='4대보험'!F11 -> 286650 | X11: ='4대보험'!H11 -> 251690 | Y11: ='4대보험'!J11 -> 32590 | Z11: ='4대보험'!L11 -> 63900 | AA11: =세금!P11 -> 673170 | AB11: =세금!Q11 -> 67310 | AC11: 0 | AD11: =SUM(W11:AC11) -> 1375310 | AE11: =T11-AD11 -> 6224690
A12: 46235 | B12: 1 | C12: =직원정보!B5 -> S0001 | D12: =직원정보!C5 -> 가온누리 | E12: =직원정보!D5 -> 대표이사실 | F12: =직원정보!E5 -> 대표이사 | G12: 6500000 | H12: =ROUND(G12/요율기준!$B$14,0) -> 31100 | I12: 4 | J12: 0 | K12: 0 | L12: =ROUND(H12*요율기준!$B$15*I12,0) -> 186600 | M12: =ROUND(H12*요율기준!$B$16*J12,0) -> 0 | N12: 500000 | O12: 100000 | P12: 0 | Q12: 100000 | R12: 200000 | S12: 200000 | T12: =G12+K12+L12+M12+N12+O12+P12+Q12+R12+S12 -> 7786600 | U12: =Q12+MIN(R12,요율기준!$B$17)+MIN(S12,요율기준!$B$18) -> 500000 | V12: =T12-U12 -> 7286600 | W12: ='4대보험'!F12 -> 286650 | X12: ='4대보험'!H12 -> 258300 | Y12: ='4대보험'!J12 -> 33440 | Z12: ='4대보험'!L12 -> 65570 | AA12: =세금!P12 -> 713930 | AB12: =세금!Q12 -> 71390 | AC12: 0 | AD12: =SUM(W12:AC12) -> 1429280 | AE12: =T12-AD12 -> 6357320
A13: 46266 | B13: 1 | C13: =직원정보!B5 -> S0001 | D13: =직원정보!C5 -> 가온누리 | E13: =직원정보!D5 -> 대표이사실 | F13: =직원정보!E5 -> 대표이사 | G13: 6500000 | H13: =ROUND(G13/요율기준!$B$14,0) -> 31100 | I13: 0 | J13: 0 | K13: 0 | L13: =ROUND(H13*요율기준!$B$15*I13,0) -> 0 | M13: =ROUND(H13*요율기준!$B$16*J13,0) -> 0 | N13: 500000 | O13: 100000 | P13: 0 | Q13: 100000 | R13: 200000 | S13: 200000 | T13: =G13+K13+L13+M13+N13+O13+P13+Q13+R13+S13 -> 7600000 | U13: =Q13+MIN(R13,요율기준!$B$17)+MIN(S13,요율기준!$B$18) -> 500000 | V13: =T13-U13 -> 7100000 | W13: ='4대보험'!F13 -> 286650 | X13: ='4대보험'!H13 -> 251690 | Y13: ='4대보험'!J13 -> 32590 | Z13: ='4대보험'!L13 -> 63900 | AA13: =세금!P13 -> 673170 | AB13: =세금!Q13 -> 67310 | AC13: 0 | AD13: =SUM(W13:AC13) -> 1375310 | AE13: =T13-AD13 -> 6224690
A14: 46296 | B14: 1 | C14: =직원정보!B5 -> S0001 | D14: =직원정보!C5 -> 가온누리 | E14: =직원정보!D5 -> 대표이사실 | F14: =직원정보!E5 -> 대표이사 | G14: 6500000 | H14: =ROUND(G14/요율기준!$B$14,0) -> 31100 | I14: 4 | J14: 0 | K14: 0 | L14: =ROUND(H14*요율기준!$B$15*I14,0) -> 186600 | M14: =ROUND(H14*요율기준!$B$16*J14,0) -> 0 | N14: 500000 | O14: 100000 | P14: 0 | Q14: 100000 | R14: 200000 | S14: 200000 | T14: =G14+K14+L14+M14+N14+O14+P14+Q14+R14+S14 -> 7786600 | U14: =Q14+MIN(R14,요율기준!$B$17)+MIN(S14,요율기준!$B$18) -> 500000 | V14: =T14-U14 -> 7286600 | W14: ='4대보험'!F14 -> 286650 | X14: ='4대보험'!H14 -> 258300 | Y14: ='4대보험'!J14 -> 33440 | Z14: ='4대보험'!L14 -> 65570 | AA14: =세금!P14 -> 713930 | AB14: =세금!Q14 -> 71390 | AC14: 0 | AD14: =SUM(W14:AC14) -> 1429280 | AE14: =T14-AD14 -> 6357320
A15: 46327 | B15: 1 | C15: =직원정보!B5 -> S0001 | D15: =직원정보!C5 -> 가온누리 | E15: =직원정보!D5 -> 대표이사실 | F15: =직원정보!E5 -> 대표이사 | G15: 6500000 | H15: =ROUND(G15/요율기준!$B$14,0) -> 31100 | I15: 0 | J15: 0 | K15: 0 | L15: =ROUND(H15*요율기준!$B$15*I15,0) -> 0 | M15: =ROUND(H15*요율기준!$B$16*J15,0) -> 0 | N15: 500000 | O15: 100000 | P15: 0 | Q15: 100000 | R15: 200000 | S15: 200000 | T15: =G15+K15+L15+M15+N15+O15+P15+Q15+R15+S15 -> 7600000 | U15: =Q15+MIN(R15,요율기준!$B$17)+MIN(S15,요율기준!$B$18) -> 500000 | V15: =T15-U15 -> 7100000 | W15: ='4대보험'!F15 -> 286650 | X15: ='4대보험'!H15 -> 251690 | Y15: ='4대보험'!J15 -> 32590 | Z15: ='4대보험'!L15 -> 63900 | AA15: =세금!P15 -> 673170 | AB15: =세금!Q15 -> 67310 | AC15: 0 | AD15: =SUM(W15:AC15) -> 1375310 | AE15: =T15-AD15 -> 6224690
A16: 46357 | B16: 1 | C16: =직원정보!B5 -> S0001 | D16: =직원정보!C5 -> 가온누리 | E16: =직원정보!D5 -> 대표이사실 | F16: =직원정보!E5 -> 대표이사 | G16: 6500000 | H16: =ROUND(G16/요율기준!$B$14,0) -> 31100 | I16: 4 | J16: 0 | K16: 0 | L16: =ROUND(H16*요율기준!$B$15*I16,0) -> 186600 | M16: =ROUND(H16*요율기준!$B$16*J16,0) -> 0 | N16: 500000 | O16: 100000 | P16: 0 | Q16: 100000 | R16: 200000 | S16: 200000 | T16: =G16+K16+L16+M16+N16+O16+P16+Q16+R16+S16 -> 7786600 | U16: =Q16+MIN(R16,요율기준!$B$17)+MIN(S16,요율기준!$B$18) -> 500000 | V16: =T16-U16 -> 7286600 | W16: ='4대보험'!F16 -> 286650 | X16: ='4대보험'!H16 -> 258300 | Y16: ='4대보험'!J16 -> 33440 | Z16: ='4대보험'!L16 -> 65570 | AA16: =세금!P16 -> 713930 | AB16: =세금!Q16 -> 71390 | AC16: 0 | AD16: =SUM(W16:AC16) -> 1429280 | AE16: =T16-AD16 -> 6357320
A17: 46023 | B17: 2 | C17: =직원정보!B6 -> S0002 | D17: =직원정보!C6 -> 나래솔 | E17: =직원정보!D6 -> 대표이사실 | F17: =직원정보!E6 -> 이사 | G17: 5200000 | H17: =ROUND(G17/요율기준!$B$14,0) -> 24880 | I17: 4 | J17: 0 | K17: 0 | L17: =ROUND(H17*요율기준!$B$15*I17,0) -> 149280 | M17: =ROUND(H17*요율기준!$B$16*J17,0) -> 0 | N17: 300000 | O17: 100000 | P17: 0 | Q17: 100000 | R17: 200000 | S17: 200000 | T17: =G17+K17+L17+M17+N17+O17+P17+Q17+R17+S17 -> 6249280 | U17: =Q17+MIN(R17,요율기준!$B$17)+MIN(S17,요율기준!$B$18) -> 500000 | V17: =T17-U17 -> 5749280 | W17: ='4대보험'!F17 -> 258710 | X17: ='4대보험'!H17 -> 203810 | Y17: ='4대보험'!J17 -> 26390 | Z17: ='4대보험'!L17 -> 51740 | AA17: =세금!P17 -> 406590 | AB17: =세금!Q17 -> 40650 | AC17: 0 | AD17: =SUM(W17:AC17) -> 987890 | AE17: =T17-AD17 -> 5261390
A18: 46054 | B18: 2 | C18: =직원정보!B6 -> S0002 | D18: =직원정보!C6 -> 나래솔 | E18: =직원정보!D6 -> 대표이사실 | F18: =직원정보!E6 -> 이사 | G18: 5200000 | H18: =ROUND(G18/요율기준!$B$14,0) -> 24880 | I18: 0 | J18: 0 | K18: 0 | L18: =ROUND(H18*요율기준!$B$15*I18,0) -> 0 | M18: =ROUND(H18*요율기준!$B$16*J18,0) -> 0 | N18: 300000 | O18: 100000 | P18: 0 | Q18: 100000 | R18: 200000 | S18: 200000 | T18: =G18+K18+L18+M18+N18+O18+P18+Q18+R18+S18 -> 6100000 | U18: =Q18+MIN(R18,요율기준!$B$17)+MIN(S18,요율기준!$B$18) -> 500000 | V18: =T18-U18 -> 5600000 | W18: ='4대보험'!F18 -> 252000 | X18: ='4대보험'!H18 -> 198520 | Y18: ='4대보험'!J18 -> 25700 | Z18: ='4대보험'!L18 -> 50400 | AA18: =세금!P18 -> 387220 | AB18: =세금!Q18 -> 38720 | AC18: 0 | AD18: =SUM(W18:AC18) -> 952560 | AE18: =T18-AD18 -> 5147440
A19: 46082 | B19: 2 | C19: =직원정보!B6 -> S0002 | D19: =직원정보!C6 -> 나래솔 | E19: =직원정보!D6 -> 대표이사실 | F19: =직원정보!E6 -> 이사 | G19: 5200000 | H19: =ROUND(G19/요율기준!$B$14,0) -> 24880 | I19: 4 | J19: 0 | K19: 0 | L19: =ROUND(H19*요율기준!$B$15*I19,0) -> 149280 | M19: =ROUND(H19*요율기준!$B$16*J19,0) -> 0 | N19: 300000 | O19: 100000 | P19: 0 | Q19: 100000 | R19: 200000 | S19: 200000 | T19: =G19+K19+L19+M19+N19+O19+P19+Q19+R19+S19 -> 6249280 | U19: =Q19+MIN(R19,요율기준!$B$17)+MIN(S19,요율기준!$B$18) -> 500000 | V19: =T19-U19 -> 5749280 | W19: ='4대보험'!F19 -> 258710 | X19: ='4대보험'!H19 -> 203810 | Y19: ='4대보험'!J19 -> 26390 | Z19: ='4대보험'!L19 -> 51740 | AA19: =세금!P19 -> 406590 | AB19: =세금!Q19 -> 40650 | AC19: 0 | AD19: =SUM(W19:AC19) -> 987890 | AE19: =T19-AD19 -> 5261390
A20: 46113 | B20: 2 | C20: =직원정보!B6 -> S0002 | D20: =직원정보!C6 -> 나래솔 | E20: =직원정보!D6 -> 대표이사실 | F20: =직원정보!E6 -> 이사 | G20: 5200000 | H20: =ROUND(G20/요율기준!$B$14,0) -> 24880 | I20: 0 | J20: 0 | K20: 0 | L20: =ROUND(H20*요율기준!$B$15*I20,0) -> 0 | M20: =ROUND(H20*요율기준!$B$16*J20,0) -> 0 | N20: 300000 | O20: 100000 | P20: 0 | Q20: 100000 | R20: 200000 | S20: 200000 | T20: =G20+K20+L20+M20+N20+O20+P20+Q20+R20+S20 -> 6100000 | U20: =Q20+MIN(R20,요율기준!$B$17)+MIN(S20,요율기준!$B$18) -> 500000 | V20: =T20-U20 -> 5600000 | W20: ='4대보험'!F20 -> 252000 | X20: ='4대보험'!H20 -> 198520 | Y20: ='4대보험'!J20 -> 25700 | Z20: ='4대보험'!L20 -> 50400 | AA20: =세금!P20 -> 387220 | AB20: =세금!Q20 -> 38720 | AC20: 0 | AD20: =SUM(W20:AC20) -> 952560 | AE20: =T20-AD20 -> 5147440
A21: 46143 | B21: 2 | C21: =직원정보!B6 -> S0002 | D21: =직원정보!C6 -> 나래솔 | E21: =직원정보!D6 -> 대표이사실 | F21: =직원정보!E6 -> 이사 | G21: 5200000 | H21: =ROUND(G21/요율기준!$B$14,0) -> 24880 | I21: 4 | J21: 0 | K21: 0 | L21: =ROUND(H21*요율기준!$B$15*I21,0) -> 149280 | M21: =ROUND(H21*요율기준!$B$16*J21,0) -> 0 | N21: 300000 | O21: 100000 | P21: 0 | Q21: 100000 | R21: 200000 | S21: 200000 | T21: =G21+K21+L21+M21+N21+O21+P21+Q21+R21+S21 -> 6249280 | U21: =Q21+MIN(R21,요율기준!$B$17)+MIN(S21,요율기준!$B$18) -> 500000 | V21: =T21-U21 -> 5749280 | W21: ='4대보험'!F21 -> 258710 | X21: ='4대보험'!H21 -> 203810 | Y21: ='4대보험'!J21 -> 26390 | Z21: ='4대보험'!L21 -> 51740 | AA21: =세금!P21 -> 406590 | AB21: =세금!Q21 -> 40650 | AC21: 0 | AD21: =SUM(W21:AC21) -> 987890 | AE21: =T21-AD21 -> 5261390
A22: 46174 | B22: 2 | C22: =직원정보!B6 -> S0002 | D22: =직원정보!C6 -> 나래솔 | E22: =직원정보!D6 -> 대표이사실 | F22: =직원정보!E6 -> 이사 | G22: 5200000 | H22: =ROUND(G22/요율기준!$B$14,0) -> 24880 | I22: 0 | J22: 0 | K22: 0 | L22: =ROUND(H22*요율기준!$B$15*I22,0) -> 0 | M22: =ROUND(H22*요율기준!$B$16*J22,0) -> 0 | N22: 300000 | O22: 100000 | P22: 0 | Q22: 100000 | R22: 200000 | S22: 200000 | T22: =G22+K22+L22+M22+N22+O22+P22+Q22+R22+S22 -> 6100000 | U22: =Q22+MIN(R22,요율기준!$B$17)+MIN(S22,요율기준!$B$18) -> 500000 | V22: =T22-U22 -> 5600000 | W22: ='4대보험'!F22 -> 252000 | X22: ='4대보험'!H22 -> 198520 | Y22: ='4대보험'!J22 -> 25700 | Z22: ='4대보험'!L22 -> 50400 | AA22: =세금!P22 -> 387220 | AB22: =세금!Q22 -> 38720 | AC22: 0 | AD22: =SUM(W22:AC22) -> 952560 | AE22: =T22-AD22 -> 5147440
A23: 46204 | B23: 2 | C23: =직원정보!B6 -> S0002 | D23: =직원정보!C6 -> 나래솔 | E23: =직원정보!D6 -> 대표이사실 | F23: =직원정보!E6 -> 이사 | G23: 5200000 | H23: =ROUND(G23/요율기준!$B$14,0) -> 24880 | I23: 4 | J23: 0 | K23: 0 | L23: =ROUND(H23*요율기준!$B$15*I23,0) -> 149280 | M23: =ROUND(H23*요율기준!$B$16*J23,0) -> 0 | N23: 300000 | O23: 100000 | P23: 0 | Q23: 100000 | R23: 200000 | S23: 200000 | T23: =G23+K23+L23+M23+N23+O23+P23+Q23+R23+S23 -> 6249280 | U23: =Q23+MIN(R23,요율기준!$B$17)+MIN(S23,요율기준!$B$18) -> 500000 | V23: =T23-U23 -> 5749280 | W23: ='4대보험'!F23 -> 258710 | X23: ='4대보험'!H23 -> 203810 | Y23: ='4대보험'!J23 -> 26390 | Z23: ='4대보험'!L23 -> 51740 | AA23: =세금!P23 -> 406590 | AB23: =세금!Q23 -> 40650 | AC23: 0 | AD23: =SUM(W23:AC23) -> 987890 | AE23: =T23-AD23 -> 5261390
A24: 46235 | B24: 2 | C24: =직원정보!B6 -> S0002 | D24: =직원정보!C6 -> 나래솔 | E24: =직원정보!D6 -> 대표이사실 | F24: =직원정보!E6 -> 이사 | G24: 5200000 | H24: =ROUND(G24/요율기준!$B$14,0) -> 24880 | I24: 0 | J24: 0 | K24: 0 | L24: =ROUND(H24*요율기준!$B$15*I24,0) -> 0 | M24: =ROUND(H24*요율기준!$B$16*J24,0) -> 0 | N24: 300000 | O24: 100000 | P24: 0 | Q24: 100000 | R24: 200000 | S24: 200000 | T24: =G24+K24+L24+M24+N24+O24+P24+Q24+R24+S24 -> 6100000 | U24: =Q24+MIN(R24,요율기준!$B$17)+MIN(S24,요율기준!$B$18) -> 500000 | V24: =T24-U24 -> 5600000 | W24: ='4대보험'!F24 -> 252000 | X24: ='4대보험'!H24 -> 198520 | Y24: ='4대보험'!J24 -> 25700 | Z24: ='4대보험'!L24 -> 50400 | AA24: =세금!P24 -> 387220 | AB24: =세금!Q24 -> 38720 | AC24: 0 | AD24: =SUM(W24:AC24) -> 952560 | AE24: =T24-AD24 -> 5147440
A25: 46266 | B25: 2 | C25: =직원정보!B6 -> S0002 | D25: =직원정보!C6 -> 나래솔 | E25: =직원정보!D6 -> 대표이사실 | F25: =직원정보!E6 -> 이사 | G25: 5200000 | H25: =ROUND(G25/요율기준!$B$14,0) -> 24880 | I25: 4 | J25: 0 | K25: 0 | L25: =ROUND(H25*요율기준!$B$15*I25,0) -> 149280 | M25: =ROUND(H25*요율기준!$B$16*J25,0) -> 0 | N25: 300000 | O25: 100000 | P25: 0 | Q25: 100000 | R25: 200000 | S25: 200000 | T25: =G25+K25+L25+M25+N25+O25+P25+Q25+R25+S25 -> 6249280 | U25: =Q25+MIN(R25,요율기준!$B$17)+MIN(S25,요율기준!$B$18) -> 500000 | V25: =T25-U25 -> 5749280 | W25: ='4대보험'!F25 -> 258710 | X25: ='4대보험'!H25 -> 203810 | Y25: ='4대보험'!J25 -> 26390 | Z25: ='4대보험'!L25 -> 51740 | AA25: =세금!P25 -> 406590 | AB25: =세금!Q25 -> 40650 | AC25: 0 | AD25: =SUM(W25:AC25) -> 987890 | AE25: =T25-AD25 -> 5261390
A26: 46296 | B26: 2 | C26: =직원정보!B6 -> S0002 | D26: =직원정보!C6 -> 나래솔 | E26: =직원정보!D6 -> 대표이사실 | F26: =직원정보!E6 -> 이사 | G26: 5200000 | H26: =ROUND(G26/요율기준!$B$14,0) -> 24880 | I26: 0 | J26: 0 | K26: 0 | L26: =ROUND(H26*요율기준!$B$15*I26,0) -> 0 | M26: =ROUND(H26*요율기준!$B$16*J26,0) -> 0 | N26: 300000 | O26: 100000 | P26: 0 | Q26: 100000 | R26: 200000 | S26: 200000 | T26: =G26+K26+L26+M26+N26+O26+P26+Q26+R26+S26 -> 6100000 | U26: =Q26+MIN(R26,요율기준!$B$17)+MIN(S26,요율기준!$B$18) -> 500000 | V26: =T26-U26 -> 5600000 | W26: ='4대보험'!F26 -> 252000 | X26: ='4대보험'!H26 -> 198520 | Y26: ='4대보험'!J26 -> 25700 | Z26: ='4대보험'!L26 -> 50400 | AA26: =세금!P26 -> 387220 | AB26: =세금!Q26 -> 38720 | AC26: 0 | AD26: =SUM(W26:AC26) -> 952560 | AE26: =T26-AD26 -> 5147440
A27: 46327 | B27: 2 | C27: =직원정보!B6 -> S0002 | D27: =직원정보!C6 -> 나래솔 | E27: =직원정보!D6 -> 대표이사실 | F27: =직원정보!E6 -> 이사 | G27: 5200000 | H27: =ROUND(G27/요율기준!$B$14,0) -> 24880 | I27: 4 | J27: 0 | K27: 0 | L27: =ROUND(H27*요율기준!$B$15*I27,0) -> 149280 | M27: =ROUND(H27*요율기준!$B$16*J27,0) -> 0 | N27: 300000 | O27: 100000 | P27: 0 | Q27: 100000 | R27: 200000 | S27: 200000 | T27: =G27+K27+L27+M27+N27+O27+P27+Q27+R27+S27 -> 6249280 | U27: =Q27+MIN(R27,요율기준!$B$17)+MIN(S27,요율기준!$B$18) -> 500000 | V27: =T27-U27 -> 5749280 | W27: ='4대보험'!F27 -> 258710 | X27: ='4대보험'!H27 -> 203810 | Y27: ='4대보험'!J27 -> 26390 | Z27: ='4대보험'!L27 -> 51740 | AA27: =세금!P27 -> 406590 | AB27: =세금!Q27 -> 40650 | AC27: 0 | AD27: =SUM(W27:AC27) -> 987890 | AE27: =T27-AD27 -> 5261390
A28: 46357 | B28: 2 | C28: =직원정보!B6 -> S0002 | D28: =직원정보!C6 -> 나래솔 | E28: =직원정보!D6 -> 대표이사실 | F28: =직원정보!E6 -> 이사 | G28: 5200000 | H28: =ROUND(G28/요율기준!$B$14,0) -> 24880 | I28: 0 | J28: 0 | K28: 0 | L28: =ROUND(H28*요율기준!$B$15*I28,0) -> 0 | M28: =ROUND(H28*요율기준!$B$16*J28,0) -> 0 | N28: 300000 | O28: 100000 | P28: 0 | Q28: 100000 | R28: 200000 | S28: 200000 | T28: =G28+K28+L28+M28+N28+O28+P28+Q28+R28+S28 -> 6100000 | U28: =Q28+MIN(R28,요율기준!$B$17)+MIN(S28,요율기준!$B$18) -> 500000 | V28: =T28-U28 -> 5600000 | W28: ='4대보험'!F28 -> 252000 | X28: ='4대보험'!H28 -> 198520 | Y28: ='4대보험'!J28 -> 25700 | Z28: ='4대보험'!L28 -> 50400 | AA28: =세금!P28 -> 387220 | AB28: =세금!Q28 -> 38720 | AC28: 0 | AD28: =SUM(W28:AC28) -> 952560 | AE28: =T28-AD28 -> 5147440
A29: 46023 | B29: 3 | C29: =직원정보!B7 -> S0003 | D29: =직원정보!C7 -> 다올찬 | E29: =직원정보!D7 -> 경영지원팀 | F29: =직원정보!E7 -> 이사 | G29: 5200000 | H29: =ROUND(G29/요율기준!$B$14,0) -> 24880 | I29: 0 | J29: 0 | K29: 0 | L29: =ROUND(H29*요율기준!$B$15*I29,0) -> 0 | M29: =ROUND(H29*요율기준!$B$16*J29,0) -> 0 | N29: 300000 | O29: 100000 | P29: 100000 | Q29: 100000 | R29: 200000 | S29: 200000 | T29: =G29+K29+L29+M29+N29+O29+P29+Q29+R29+S29 -> 6200000 | U29: =Q29+MIN(R29,요율기준!$B$17)+MIN(S29,요율기준!$B$18) -> 500000 | V29: =T29-U29 -> 5700000 | W29: ='4대보험'!F29 -> 256500 | X29: ='4대보험'!H29 -> 202060 | Y29: ='4대보험'!J29 -> 26160 | Z29: ='4대보험'!L29 -> 51300 | AA29: =세금!P29 -> 400200 | AB29: =세금!Q29 -> 40020 | AC29: 0 | AD29: =SUM(W29:AC29) -> 976240 | AE29: =T29-AD29 -> 5223760
A30: 46054 | B30: 3 | C30: =직원정보!B7 -> S0003 | D30: =직원정보!C7 -> 다올찬 | E30: =직원정보!D7 -> 경영지원팀 | F30: =직원정보!E7 -> 이사 | G30: 5200000 | H30: =ROUND(G30/요율기준!$B$14,0) -> 24880 | I30: 4 | J30: 0 | K30: 0 | L30: =ROUND(H30*요율기준!$B$15*I30,0) -> 149280 | M30: =ROUND(H30*요율기준!$B$16*J30,0) -> 0 | N30: 300000 | O30: 100000 | P30: 100000 | Q30: 100000 | R30: 200000 | S30: 200000 | T30: =G30+K30+L30+M30+N30+O30+P30+Q30+R30+S30 -> 6349280 | U30: =Q30+MIN(R30,요율기준!$B$17)+MIN(S30,요율기준!$B$18) -> 500000 | V30: =T30-U30 -> 5849280 | W30: ='4대보험'!F30 -> 263210 | X30: ='4대보험'!H30 -> 207350 | Y30: ='4대보험'!J30 -> 26850 | Z30: ='4대보험'!L30 -> 52640 | AA30: =세금!P30 -> 427540 | AB30: =세금!Q30 -> 42750 | AC30: 0 | AD30: =SUM(W30:AC30) -> 1020340 | AE30: =T30-AD30 -> 5328940
A31: 46082 | B31: 3 | C31: =직원정보!B7 -> S0003 | D31: =직원정보!C7 -> 다올찬 | E31: =직원정보!D7 -> 경영지원팀 | F31: =직원정보!E7 -> 이사 | G31: 5200000 | H31: =ROUND(G31/요율기준!$B$14,0) -> 24880 | I31: 0 | J31: 0 | K31: 0 | L31: =ROUND(H31*요율기준!$B$15*I31,0) -> 0 | M31: =ROUND(H31*요율기준!$B$16*J31,0) -> 0 | N31: 300000 | O31: 100000 | P31: 100000 | Q31: 100000 | R31: 200000 | S31: 200000 | T31: =G31+K31+L31+M31+N31+O31+P31+Q31+R31+S31 -> 6200000 | U31: =Q31+MIN(R31,요율기준!$B$17)+MIN(S31,요율기준!$B$18) -> 500000 | V31: =T31-U31 -> 5700000 | W31: ='4대보험'!F31 -> 256500 | X31: ='4대보험'!H31 -> 202060 | Y31: ='4대보험'!J31 -> 26160 | Z31: ='4대보험'!L31 -> 51300 | AA31: =세금!P31 -> 400200 | AB31: =세금!Q31 -> 40020 | AC31: 0 | AD31: =SUM(W31:AC31) -> 976240 | AE31: =T31-AD31 -> 5223760
A32: 46113 | B32: 3 | C32: =직원정보!B7 -> S0003 | D32: =직원정보!C7 -> 다올찬 | E32: =직원정보!D7 -> 경영지원팀 | F32: =직원정보!E7 -> 이사 | G32: 5200000 | H32: =ROUND(G32/요율기준!$B$14,0) -> 24880 | I32: 4 | J32: 0 | K32: 0 | L32: =ROUND(H32*요율기준!$B$15*I32,0) -> 149280 | M32: =ROUND(H32*요율기준!$B$16*J32,0) -> 0 | N32: 300000 | O32: 100000 | P32: 100000 | Q32: 100000 | R32: 200000 | S32: 200000 | T32: =G32+K32+L32+M32+N32+O32+P32+Q32+R32+S32 -> 6349280 | U32: =Q32+MIN(R32,요율기준!$B$17)+MIN(S32,요율기준!$B$18) -> 500000 | V32: =T32-U32 -> 5849280 | W32: ='4대보험'!F32 -> 263210 | X32: ='4대보험'!H32 -> 207350 | Y32: ='4대보험'!J32 -> 26850 | Z32: ='4대보험'!L32 -> 52640 | AA32: =세금!P32 -> 427540 | AB32: =세금!Q32 -> 42750 | AC32: 0 | AD32: =SUM(W32:AC32) -> 1020340 | AE32: =T32-AD32 -> 5328940
A33: 46143 | B33: 3 | C33: =직원정보!B7 -> S0003 | D33: =직원정보!C7 -> 다올찬 | E33: =직원정보!D7 -> 경영지원팀 | F33: =직원정보!E7 -> 이사 | G33: 5200000 | H33: =ROUND(G33/요율기준!$B$14,0) -> 24880 | I33: 0 | J33: 0 | K33: 0 | L33: =ROUND(H33*요율기준!$B$15*I33,0) -> 0 | M33: =ROUND(H33*요율기준!$B$16*J33,0) -> 0 | N33: 300000 | O33: 100000 | P33: 100000 | Q33: 100000 | R33: 200000 | S33: 200000 | T33: =G33+K33+L33+M33+N33+O33+P33+Q33+R33+S33 -> 6200000 | U33: =Q33+MIN(R33,요율기준!$B$17)+MIN(S33,요율기준!$B$18) -> 500000 | V33: =T33-U33 -> 5700000 | W33: ='4대보험'!F33 -> 256500 | X33: ='4대보험'!H33 -> 202060 | Y33: ='4대보험'!J33 -> 26160 | Z33: ='4대보험'!L33 -> 51300 | AA33: =세금!P33 -> 400200 | AB33: =세금!Q33 -> 40020 | AC33: 0 | AD33: =SUM(W33:AC33) -> 976240 | AE33: =T33-AD33 -> 5223760
A34: 46174 | B34: 3 | C34: =직원정보!B7 -> S0003 | D34: =직원정보!C7 -> 다올찬 | E34: =직원정보!D7 -> 경영지원팀 | F34: =직원정보!E7 -> 이사 | G34: 5200000 | H34: =ROUND(G34/요율기준!$B$14,0) -> 24880 | I34: 4 | J34: 0 | K34: 0 | L34: =ROUND(H34*요율기준!$B$15*I34,0) -> 149280 | M34: =ROUND(H34*요율기준!$B$16*J34,0) -> 0 | N34: 300000 | O34: 100000 | P34: 100000 | Q34: 100000 | R34: 200000 | S34: 200000 | T34: =G34+K34+L34+M34+N34+O34+P34+Q34+R34+S34 -> 6349280 | U34: =Q34+MIN(R34,요율기준!$B$17)+MIN(S34,요율기준!$B$18) -> 500000 | V34: =T34-U34 -> 5849280 | W34: ='4대보험'!F34 -> 263210 | X34: ='4대보험'!H34 -> 207350 | Y34: ='4대보험'!J34 -> 26850 | Z34: ='4대보험'!L34 -> 52640 | AA34: =세금!P34 -> 427540 | AB34: =세금!Q34 -> 42750 | AC34: 0 | AD34: =SUM(W34:AC34) -> 1020340 | AE34: =T34-AD34 -> 5328940
A35: 46204 | B35: 3 | C35: =직원정보!B7 -> S0003 | D35: =직원정보!C7 -> 다올찬 | E35: =직원정보!D7 -> 경영지원팀 | F35: =직원정보!E7 -> 이사 | G35: 5200000 | H35: =ROUND(G35/요율기준!$B$14,0) -> 24880 | I35: 0 | J35: 0 | K35: 0 | L35: =ROUND(H35*요율기준!$B$15*I35,0) -> 0 | M35: =ROUND(H35*요율기준!$B$16*J35,0) -> 0 | N35: 300000 | O35: 100000 | P35: 100000 | Q35: 100000 | R35: 200000 | S35: 200000 | T35: =G35+K35+L35+M35+N35+O35+P35+Q35+R35+S35 -> 6200000 | U35: =Q35+MIN(R35,요율기준!$B$17)+MIN(S35,요율기준!$B$18) -> 500000 | V35: =T35-U35 -> 5700000 | W35: ='4대보험'!F35 -> 256500 | X35: ='4대보험'!H35 -> 202060 | Y35: ='4대보험'!J35 -> 26160 | Z35: ='4대보험'!L35 -> 51300 | AA35: =세금!P35 -> 400200 | AB35: =세금!Q35 -> 40020 | AC35: 0 | AD35: =SUM(W35:AC35) -> 976240 | AE35: =T35-AD35 -> 5223760
A36: 46235 | B36: 3 | C36: =직원정보!B7 -> S0003 | D36: =직원정보!C7 -> 다올찬 | E36: =직원정보!D7 -> 경영지원팀 | F36: =직원정보!E7 -> 이사 | G36: 5200000 | H36: =ROUND(G36/요율기준!$B$14,0) -> 24880 | I36: 4 | J36: 0 | K36: 0 | L36: =ROUND(H36*요율기준!$B$15*I36,0) -> 149280 | M36: =ROUND(H36*요율기준!$B$16*J36,0) -> 0 | N36: 300000 | O36: 100000 | P36: 100000 | Q36: 100000 | R36: 200000 | S36: 200000 | T36: =G36+K36+L36+M36+N36+O36+P36+Q36+R36+S36 -> 6349280 | U36: =Q36+MIN(R36,요율기준!$B$17)+MIN(S36,요율기준!$B$18) -> 500000 | V36: =T36-U36 -> 5849280 | W36: ='4대보험'!F36 -> 263210 | X36: ='4대보험'!H36 -> 207350 | Y36: ='4대보험'!J36 -> 26850 | Z36: ='4대보험'!L36 -> 52640 | AA36: =세금!P36 -> 427540 | AB36: =세금!Q36 -> 42750 | AC36: 0 | AD36: =SUM(W36:AC36) -> 1020340 | AE36: =T36-AD36 -> 5328940
A37: 46266 | B37: 3 | C37: =직원정보!B7 -> S0003 | D37: =직원정보!C7 -> 다올찬 | E37: =직원정보!D7 -> 경영지원팀 | F37: =직원정보!E7 -> 이사 | G37: 5200000 | H37: =ROUND(G37/요율기준!$B$14,0) -> 24880 | I37: 0 | J37: 0 | K37: 0 | L37: =ROUND(H37*요율기준!$B$15*I37,0) -> 0 | M37: =ROUND(H37*요율기준!$B$16*J37,0) -> 0 | N37: 300000 | O37: 100000 | P37: 100000 | Q37: 100000 | R37: 200000 | S37: 200000 | T37: =G37+K37+L37+M37+N37+O37+P37+Q37+R37+S37 -> 6200000 | U37: =Q37+MIN(R37,요율기준!$B$17)+MIN(S37,요율기준!$B$18) -> 500000 | V37: =T37-U37 -> 5700000 | W37: ='4대보험'!F37 -> 256500 | X37: ='4대보험'!H37 -> 202060 | Y37: ='4대보험'!J37 -> 26160 | Z37: ='4대보험'!L37 -> 51300 | AA37: =세금!P37 -> 400200 | AB37: =세금!Q37 -> 40020 | AC37: 0 | AD37: =SUM(W37:AC37) -> 976240 | AE37: =T37-AD37 -> 5223760
A38: 46296 | B38: 3 | C38: =직원정보!B7 -> S0003 | D38: =직원정보!C7 -> 다올찬 | E38: =직원정보!D7 -> 경영지원팀 | F38: =직원정보!E7 -> 이사 | G38: 5200000 | H38: =ROUND(G38/요율기준!$B$14,0) -> 24880 | I38: 4 | J38: 0 | K38: 0 | L38: =ROUND(H38*요율기준!$B$15*I38,0) -> 149280 | M38: =ROUND(H38*요율기준!$B$16*J38,0) -> 0 | N38: 300000 | O38: 100000 | P38: 100000 | Q38: 100000 | R38: 200000 | S38: 200000 | T38: =G38+K38+L38+M38+N38+O38+P38+Q38+R38+S38 -> 6349280 | U38: =Q38+MIN(R38,요율기준!$B$17)+MIN(S38,요율기준!$B$18) -> 500000 | V38: =T38-U38 -> 5849280 | W38: ='4대보험'!F38 -> 263210 | X38: ='4대보험'!H38 -> 207350 | Y38: ='4대보험'!J38 -> 26850 | Z38: ='4대보험'!L38 -> 52640 | AA38: =세금!P38 -> 427540 | AB38: =세금!Q38 -> 42750 | AC38: 0 | AD38: =SUM(W38:AC38) -> 1020340 | AE38: =T38-AD38 -> 5328940
A39: 46327 | B39: 3 | C39: =직원정보!B7 -> S0003 | D39: =직원정보!C7 -> 다올찬 | E39: =직원정보!D7 -> 경영지원팀 | F39: =직원정보!E7 -> 이사 | G39: 5200000 | H39: =ROUND(G39/요율기준!$B$14,0) -> 24880 | I39: 0 | J39: 0 | K39: 0 | L39: =ROUND(H39*요율기준!$B$15*I39,0) -> 0 | M39: =ROUND(H39*요율기준!$B$16*J39,0) -> 0 | N39: 300000 | O39: 100000 | P39: 100000 | Q39: 100000 | R39: 200000 | S39: 200000 | T39: =G39+K39+L39+M39+N39+O39+P39+Q39+R39+S39 -> 6200000 | U39: =Q39+MIN(R39,요율기준!$B$17)+MIN(S39,요율기준!$B$18) -> 500000 | V39: =T39-U39 -> 5700000 | W39: ='4대보험'!F39 -> 256500 | X39: ='4대보험'!H39 -> 202060 | Y39: ='4대보험'!J39 -> 26160 | Z39: ='4대보험'!L39 -> 51300 | AA39: =세금!P39 -> 400200 | AB39: =세금!Q39 -> 40020 | AC39: 0 | AD39: =SUM(W39:AC39) -> 976240 | AE39: =T39-AD39 -> 5223760
A40: 46357 | B40: 3 | C40: =직원정보!B7 -> S0003 | D40: =직원정보!C7 -> 다올찬 | E40: =직원정보!D7 -> 경영지원팀 | F40: =직원정보!E7 -> 이사 | G40: 5200000 | H40: =ROUND(G40/요율기준!$B$14,0) -> 24880 | I40: 4 | J40: 0 | K40: 0 | L40: =ROUND(H40*요율기준!$B$15*I40,0) -> 149280 | M40: =ROUND(H40*요율기준!$B$16*J40,0) -> 0 | N40: 300000 | O40: 100000 | P40: 100000 | Q40: 100000 | R40: 200000 | S40: 200000 | T40: =G40+K40+L40+M40+N40+O40+P40+Q40+R40+S40 -> 6349280 | U40: =Q40+MIN(R40,요율기준!$B$17)+MIN(S40,요율기준!$B$18) -> 500000 | V40: =T40-U40 -> 5849280 | W40: ='4대보험'!F40 -> 263210 | X40: ='4대보험'!H40 -> 207350 | Y40: ='4대보험'!J40 -> 26850 | Z40: ='4대보험'!L40 -> 52640 | AA40: =세금!P40 -> 427540 | AB40: =세금!Q40 -> 42750 | AC40: 0 | AD40: =SUM(W40:AC40) -> 1020340 | AE40: =T40-AD40 -> 5328940
...

Sheet 4대보험
A1: 4대보험 부담금 내역 (자동계산) — 성명 필터 가능
A2: ※ 보수월액=급여대장 과세급여. 요율은 '요율기준' 참조, 10원 미만 절사(TRUNC). | E2: =SUBTOTAL(109,E5:E220) -> 999745137 | F2: =SUBTOTAL(109,F5:F220) -> 44543040 | G2: =SUBTOTAL(109,G5:G220) -> 44543040 | H2: =SUBTOTAL(109,H5:H220) -> 35439950 | I2: =SUBTOTAL(109,I5:I220) -> 35439950 | J2: =SUBTOTAL(109,J5:J220) -> 4588390 | K2: =SUBTOTAL(109,K5:K220) -> 4588390 | L2: =SUBTOTAL(109,L5:L220) -> 8996700 | ... Q2: =SUBTOTAL(109,Q5:Q220) -> 204330800
A3: 기본정보 | E3: 보수월액 | F3: 국민연금 | H3: 건강보험 | J3: 장기요양 | L3: 고용보험 | N3: 산재 | O3: 부담 합계
A4: 귀속월 | B4: NO | C4: 성명 | D4: 부서 | E4: 보수월액 | F4: 근로자 | G4: 회사 | H4: 근로자 | I4: 회사 | J4: 근로자 | K4: 회사 | L4: 근로자 | M4: 회사 | N4: 회사 | O4: 근로자 부담계 | P4: 회사 부담계 | Q4: 총부담액
A5: =급여대장!A5 -> 46023 | B5: 1 | C5: =급여대장!D5 -> 가온누리 | D5: =급여대장!E5 -> 대표이사실 | E5: =급여대장!V5 -> 7100000 | F5: =TRUNC(MIN(MAX(E5,요율기준!$B$6),요율기준!$B$5)*요율기준!$B$4,-1) -> 286650 | G5: =F5 -> 286650 | H5: =TRUNC(E5*요율기준!$B$7,-1) -> 251690 | I5: =H5 -> 251690 | J5: =TRUNC(H5*요율기준!$B$8,-1) -> 32590 | K5: =J5 -> 32590 | L5: =TRUNC(E5*요율기준!$B$9,-1) -> 63900 | M5: =TRUNC(E5*요율기준!$B$10,-1) -> 81650 | N5: =TRUNC(E5*요율기준!$B$11,-1) -> 104370 | O5: =F5+H5+J5+L5 -> 634830 | P5: =G5+I5+K5+M5+N5 -> 756950 | Q5: =O5+P5 -> 1391780
A6: =급여대장!A6 -> 46054 | B6: 1 | C6: =급여대장!D6 -> 가온누리 | D6: =급여대장!E6 -> 대표이사실 | E6: =급여대장!V6 -> 7286600 | F6: =TRUNC(MIN(MAX(E6,요율기준!$B$6),요율기준!$B$5)*요율기준!$B$4,-1) -> 286650 | G6: =F6 -> 286650 | H6: =TRUNC(E6*요율기준!$B$7,-1) -> 258300 | I6: =H6 -> 258300 | J6: =TRUNC(H6*요율기준!$B$8,-1) -> 33440 | K6: =J6 -> 33440 | L6: =TRUNC(E6*요율기준!$B$9,-1) -> 65570 | M6: =TRUNC(E6*요율기준!$B$10,-1) -> 83790 | N6: =TRUNC(E6*요율기준!$B$11,-1) -> 107110 | O6: =F6+H6+J6+L6 -> 643960 | P6: =G6+I6+K6+M6+N6 -> 769290 | Q6: =O6+P6 -> 1413250
A7: =급여대장!A7 -> 46082 | B7: 1 | C7: =급여대장!D7 -> 가온누리 | D7: =급여대장!E7 -> 대표이사실 | E7: =급여대장!V7 -> 7100000 | F7: =TRUNC(MIN(MAX(E7,요율기준!$B$6),요율기준!$B$5)*요율기준!$B$4,-1) -> 286650 | G7: =F7 -> 286650 | H7: =TRUNC(E7*요율기준!$B$7,-1) -> 251690 | I7: =H7 -> 251690 | J7: =TRUNC(H7*요율기준!$B$8,-1) -> 32590 | K7: =J7 -> 32590 | L7: =TRUNC(E7*요율기준!$B$9,-1) -> 63900 | M7: =TRUNC(E7*요율기준!$B$10,-1) -> 81650 | N7: =TRUNC(E7*요율기준!$B$11,-1) -> 104370 | O7: =F7+H7+J7+L7 -> 634830 | P7: =G7+I7+K7+M7+N7 -> 756950 | Q7: =O7+P7 -> 1391780
A8: =급여대장!A8 -> 46113 | B8: 1 | C8: =급여대장!D8 -> 가온누리 | D8: =급여대장!E8 -> 대표이사실 | E8: =급여대장!V8 -> 7286600 | F8: =TRUNC(MIN(MAX(E8,요율기준!$B$6),요율기준!$B$5)*요율기준!$B$4,-1) -> 286650 | G8: =F8 -> 286650 | H8: =TRUNC(E8*요율기준!$B$7,-1) -> 258300 | I8: =H8 -> 258300 | J8: =TRUNC(H8*요율기준!$B$8,-1) -> 33440 | K8: =J8 -> 33440 | L8: =TRUNC(E8*요율기준!$B$9,-1) -> 65570 | M8: =TRUNC(E8*요율기준!$B$10,-1) -> 83790 | N8: =TRUNC(E8*요율기준!$B$11,-1) -> 107110 | O8: =F8+H8+J8+L8 -> 643960 | P8: =G8+I8+K8+M8+N8 -> 769290 | Q8: =O8+P8 -> 1413250
A9: =급여대장!A9 -> 46143 | B9: 1 | C9: =급여대장!D9 -> 가온누리 | D9: =급여대장!E9 -> 대표이사실 | E9: =급여대장!V9 -> 7100000 | F9: =TRUNC(MIN(MAX(E9,요율기준!$B$6),요율기준!$B$5)*요율기준!$B$4,-1) -> 286650 | G9: =F9 -> 286650 | H9: =TRUNC(E9*요율기준!$B$7,-1) -> 251690 | I9: =H9 -> 251690 | J9: =TRUNC(H9*요율기준!$B$8,-1) -> 32590 | K9: =J9 -> 32590 | L9: =TRUNC(E9*요율기준!$B$9,-1) -> 63900 | M9: =TRUNC(E9*요율기준!$B$10,-1) -> 81650 | N9: =TRUNC(E9*요율기준!$B$11,-1) -> 104370 | O9: =F9+H9+J9+L9 -> 634830 | P9: =G9+I9+K9+M9+N9 -> 756950 | Q9: =O9+P9 -> 1391780
A10: =급여대장!A10 -> 46174 | B10: 1 | C10: =급여대장!D10 -> 가온누리 | D10: =급여대장!E10 -> 대표이사실 | E10: =급여대장!V10 -> 7286600 | F10: =TRUNC(MIN(MAX(E10,요율기준!$B$6),요율기준!$B$5)*요율기준!$B$4,-1) -> 286650 | G10: =F10 -> 286650 | H10: =TRUNC(E10*요율기준!$B$7,-1) -> 258300 | I10: =H10 -> 258300 | J10: =TRUNC(H10*요율기준!$B$8,-1) -> 33440 | K10: =J10 -> 33440 | L10: =TRUNC(E10*요율기준!$B$9,-1) -> 65570 | M10: =TRUNC(E10*요율기준!$B$10,-1) -> 83790 | N10: =TRUNC(E10*요율기준!$B$11,-1) -> 107110 | O10: =F10+H10+J10+L10 -> 643960 | P10: =G10+I10+K10+M10+N10 -> 769290 | Q10: =O10+P10 -> 1413250
A11: =급여대장!A11 -> 46204 | B11: 1 | C11: =급여대장!D11 -> 가온누리 | D11: =급여대장!E11 -> 대표이사실 | E11: =급여대장!V11 -> 7100000 | F11: =TRUNC(MIN(MAX(E11,요율기준!$B$6),요율기준!$B$5)*요율기준!$B$4,-1) -> 286650 | G11: =F11 -> 286650 | H11: =TRUNC(E11*요율기준!$B$7,-1) -> 251690 | I11: =H11 -> 251690 | J11: =TRUNC(H11*요율기준!$B$8,-1) -> 32590 | K11: =J11 -> 32590 | L11: =TRUNC(E11*요율기준!$B$9,-1) -> 63900 | M11: =TRUNC(E11*요율기준!$B$10,-1) -> 81650 | N11: =TRUNC(E11*요율기준!$B$11,-1) -> 104370 | O11: =F11+H11+J11+L11 -> 634830 | P11: =G11+I11+K11+M11+N11 -> 756950 | Q11: =O11+P11 -> 1391780
A12: =급여대장!A12 -> 46235 | B12: 1 | C12: =급여대장!D12 -> 가온누리 | D12: =급여대장!E12 -> 대표이사실 | E12: =급여대장!V12 -> 7286600 | F12: =TRUNC(MIN(MAX(E12,요율기준!$B$6),요율기준!$B$5)*요율기준!$B$4,-1) -> 286650 | G12: =F12 -> 286650 | H12: =TRUNC(E12*요율기준!$B$7,-1) -> 258300 | I12: =H12 -> 258300 | J12: =TRUNC(H12*요율기준!$B$8,-1) -> 33440 | K12: =J12 -> 33440 | L12: =TRUNC(E12*요율기준!$B$9,-1) -> 65570 | M12: =TRUNC(E12*요율기준!$B$10,-1) -> 83790 | N12: =TRUNC(E12*요율기준!$B$11,-1) -> 107110 | O12: =F12+H12+J12+L12 -> 643960 | P12: =G12+I12+K12+M12+N12 -> 769290 | Q12: =O12+P12 -> 1413250
A13: =급여대장!A13 -> 46266 | B13: 1 | C13: =급여대장!D13 -> 가온누리 | D13: =급여대장!E13 -> 대표이사실 | E13: =급여대장!V13 -> 7100000 | F13: =TRUNC(MIN(MAX(E13,요율기준!$B$6),요율기준!$B$5)*요율기준!$B$4,-1) -> 286650 | G13: =F13 -> 286650 | H13: =TRUNC(E13*요율기준!$B$7,-1) -> 251690 | I13: =H13 -> 251690 | J13: =TRUNC(H13*요율기준!$B$8,-1) -> 32590 | K13: =J13 -> 32590 | L13: =TRUNC(E13*요율기준!$B$9,-1) -> 63900 | M13: =TRUNC(E13*요율기준!$B$10,-1) -> 81650 | N13: =TRUNC(E13*요율기준!$B$11,-1) -> 104370 | O13: =F13+H13+J13+L13 -> 634830 | P13: =G13+I13+K13+M13+N13 -> 756950 | Q13: =O13+P13 -> 1391780
A14: =급여대장!A14 -> 46296 | B14: 1 | C14: =급여대장!D14 -> 가온누리 | D14: =급여대장!E14 -> 대표이사실 | E14: =급여대장!V14 -> 7286600 | F14: =TRUNC(MIN(MAX(E14,요율기준!$B$6),요율기준!$B$5)*요율기준!$B$4,-1) -> 286650 | G14: =F14 -> 286650 | H14: =TRUNC(E14*요율기준!$B$7,-1) -> 258300 | I14: =H14 -> 258300 | J14: =TRUNC(H14*요율기준!$B$8,-1) -> 33440 | K14: =J14 -> 33440 | L14: =TRUNC(E14*요율기준!$B$9,-1) -> 65570 | M14: =TRUNC(E14*요율기준!$B$10,-1) -> 83790 | N14: =TRUNC(E14*요율기준!$B$11,-1) -> 107110 | O14: =F14+H14+J14+L14 -> 643960 | P14: =G14+I14+K14+M14+N14 -> 769290 | Q14: =O14+P14 -> 1413250
A15: =급여대장!A15 -> 46327 | B15: 1 | C15: =급여대장!D15 -> 가온누리 | D15: =급여대장!E15 -> 대표이사실 | E15: =급여대장!V15 -> 7100000 | F15: =TRUNC(MIN(MAX(E15,요율기준!$B$6),요율기준!$B$5)*요율기준!$B$4,-1) -> 286650 | G15: =F15 -> 286650 | H15: =TRUNC(E15*요율기준!$B$7,-1) -> 251690 | I15: =H15 -> 251690 | J15: =TRUNC(H15*요율기준!$B$8,-1) -> 32590 | K15: =J15 -> 32590 | L15: =TRUNC(E15*요율기준!$B$9,-1) -> 63900 | M15: =TRUNC(E15*요율기준!$B$10,-1) -> 81650 | N15: =TRUNC(E15*요율기준!$B$11,-1) -> 104370 | O15: =F15+H15+J15+L15 -> 634830 | P15: =G15+I15+K15+M15+N15 -> 756950 | Q15: =O15+P15 -> 1391780
A16: =급여대장!A16 -> 46357 | B16: 1 | C16: =급여대장!D16 -> 가온누리 | D16: =급여대장!E16 -> 대표이사실 | E16: =급여대장!V16 -> 7286600 | F16: =TRUNC(MIN(MAX(E16,요율기준!$B$6),요율기준!$B$5)*요율기준!$B$4,-1) -> 286650 | G16: =F16 -> 286650 | H16: =TRUNC(E16*요율기준!$B$7,-1) -> 258300 | I16: =H16 -> 258300 | J16: =TRUNC(H16*요율기준!$B$8,-1) -> 33440 | K16: =J16 -> 33440 | L16: =TRUNC(E16*요율기준!$B$9,-1) -> 65570 | M16: =TRUNC(E16*요율기준!$B$10,-1) -> 83790 | N16: =TRUNC(E16*요율기준!$B$11,-1) -> 107110 | O16: =F16+H16+J16+L16 -> 643960 | P16: =G16+I16+K16+M16+N16 -> 769290 | Q16: =O16+P16 -> 1413250
... A220: =급여대장!A220 -> 46357 | B220: 18 | C220: =급여대장!D220 -> 온새미 | D220: =급여대장!E220 -> 현장지원 | E220: =급여대장!V220 -> 3452787 | F220: =TRUNC(MIN(MAX(E220,요율기준!$B$6),요율기준!$B$5)*요율기준!$B$4,-1) -> 155370 | G220: =F220 -> 155370 | H220: =TRUNC(E220*요율기준!$B$7,-1) -> 122400 | I220: =H220 -> 122400 | J220: =TRUNC(H220*요율기준!$B$8,-1) -> 15850 | K220: =J220 -> 15850 | L220: =TRUNC(E220*요율기준!$B$9,-1) -> 31070 | M220: =TRUNC(E220*요율기준!$B$10,-1) -> 39700 | N220: =TRUNC(E220*요율기준!$B$11,-1) -> 50750 | O220: =F220+H220+J220+L220 -> 324690 | P220: =G220+I220+K220+M220+N220 -> 384070 | Q220: =O220+P220 -> 708760

Sheet 세금
A1: 근로소득세(갑근세)·지방소득세 산출 (자동계산) — 성명 필터 가능
A2: ※ 근로소득 간이세액표 산출 로직의 근사치입니다. 신고 전 홈택스 간이세액표와 대조하세요. 10원 미만 절사. | E2: =SUBTOTAL(109,E5:E220) -> 999745137 | P2: =SUBTOTAL(109,P5:P220) -> 57938410 | Q2: =SUBTOTAL(109,Q5:Q220) -> 5792900 | R2: =SUBTOTAL(109,R5:R220) -> 63731310
A4: 귀속월 | B4: NO | C4: 성명 | D4: 부양 가족수 | E4: 월 과세급여 | F4: 연간환산 | G4: 근로소득 공제 | H4: 근로소득 금액 | I4: 인적공제 | J4: 연금보험료 공제 | K4: 특별공제 (가정) | L4: 과세표준 | M4: 산출세액(연) | N4: 근로소득 세액공제 | O4: 결정세액(연) | P4: 소득세(월) | Q4: 지방소득세(월) | R4: 원천징수계(월)
A5: =급여대장!A5 -> 46023 | B5: 1 | C5: =급여대장!D5 -> 가온누리 | D5: =직원정보!I5 -> 1 | E5: =급여대장!V5 -> 7100000 | F5: =E5*12 -> 85200000 | G5: =MIN(20000000,IF(F5<=5000000,F5*0.7,IF(F5<=15000000,3500000+(F5-5000000)*0.4,IF(F5<=45000000,7500000+(F5-15000000)*0.15,IF(F5<=100000000,12000000+(F5-45000000)*0.05,14750000+(F5-100000000)*0.02))))) -> 14010000 | H5: =F5-G5 -> 71190000 | I5: =D5*요율기준!$B$13 -> 1500000 | J5: ='4대보험'!F5*12 -> 3439800 | K5: =IF(D5=1,3100000+F5*0.04,IF(D5=2,3600000+F5*0.04,5000000+F5*0.07)) -> 6508000 | L5: =MAX(0,H5-I5-J5-K5) -> 59742200 | M5: =IF(L5<=14000000,L5*0.06,IF(L5<=50000000,840000+(L5-14000000)*0.15,IF(L5<=88000000,6240000+(L5-50000000)*0.24,IF(L5<=150000000,15360000+(L5-88000000)*0.35,IF(L5<=300000000,37060000+(L5-150000000)*0.38,IF(L5<=500000000,94060000+(L5-300000000)*0.4,IF(L5<=1000000000,174060000+(L5-500000000)*0.42,384060000+(L5-1000000000)*0.45))))))) -> 8578128 | N5: =MIN(IF(M5<=1300000,M5*0.55,715000+(M5-1300000)*0.3),IF(F5<=33000000,740000,IF(F5<=70000000,MAX(660000,740000-(F5-33000000)*0.008),MAX(500000,660000-(F5-70000000)*0.5)))) -> 500000 | O5: =MAX(0,M5-N5) -> 8078128 | P5: =TRUNC(O5/12,-1) -> 673170 | Q5: =TRUNC(P5*요율기준!$B$12,-1) -> 67310 | R5: =P5+Q5 -> 740480
A6: =급여대장!A6 -> 46054 | B6: 1 | C6: =급여대장!D6 -> 가온누리 | D6: =직원정보!I5 -> 1 | E6: =급여대장!V6 -> 7286600 | F6: =E6*12 -> 87439200 | G6: =MIN(20000000,IF(F6<=5000000,F6*0.7,IF(F6<=15000000,3500000+(F6-5000000)*0.4,IF(F6<=45000000,7500000+(F6-15000000)*0.15,IF(F6<=100000000,12000000+(F6-45000000)*0.05,14750000+(F6-100000000)*0.02))))) -> 14121960 | H6: =F6-G6 -> 73317240 | I6: =D6*요율기준!$B$13 -> 1500000 | J6: ='4대보험'!F6*12 -> 3439800 | K6: =IF(D6=1,3100000+F6*0.04,IF(D6=2,3600000+F6*0.04,5000000+F6*0.07)) -> 6597568 | L6: =MAX(0,H6-I6-J6-K6) -> 61779872 | M6: =IF(L6<=14000000,L6*0.06,IF(L6<=50000000,840000+(L6-14000000)*0.15,IF(L6<=88000000,6240000+(L6-50000000)*0.24,IF(L6<=150000000,15360000+(L6-88000000)*0.35,IF(L6<=300000000,37060000+(L6-150000000)*0.38,IF(L6<=500000000,94060000+(L6-300000000)*0.4,IF(L6<=1000000000,174060000+(L6-500000000)*0.42,384060000+(L6-1000000000)*0.45))))))) -> 9067169.3 | N6: =MIN(IF(M6<=1300000,M6*0.55,715000+(M6-1300000)*0.3),IF(F6<=33000000,740000,IF(F6<=70000000,MAX(660000,740000-(F6-33000000)*0.008),MAX(500000,660000-(F6-70000000)*0.5)))) -> 500000 | O6: =MAX(0,M6-N6) -> 8567169.3 | P6: =TRUNC(O6/12,-1) -> 713930 | Q6: =TRUNC(P6*요율기준!$B$12,-1) -> 71390 | R6: =P6+Q6 -> 785320
A7: =급여대장!A7 -> 46082 | B7: 1 | C7: =급여대장!D7 -> 가온누리 | D7: =직원정보!I5 -> 1 | E7: =급여대장!V7 -> 7100000 | F7: =E7*12 -> 85200000 | G7: =MIN(20000000,IF(F7<=5000000,F7*0.7,IF(F7<=15000000,3500000+(F7-5000000)*0.4,IF(F7<=45000000,7500000+(F7-15000000)*0.15,IF(F7<=100000000,12000000+(F7-45000000)*0.05,14750000+(F7-100000000)*0.02))))) -> 14010000 | H7: =F7-G7 -> 71190000 | I7: =D7*요율기준!$B$13 -> 1500000 | J7: ='4대보험'!F7*12 -> 3439800 | K7: =IF(D7=1,3100000+F7*0.04,IF(D7=2,3600000+F7*0.04,5000000+F7*0.07)) -> 6508000 | L7: =MAX(0,H7-I7-J7-K7) -> 59742200 | M7: =IF(L7<=14000000,L7*0.06,IF(L7<=50000000,840000+(L7-14000000)*0.15,IF(L7<=88000000,6240000+(L7-50000000)*0.24,IF(L7<=150000000,15360000+(L7-88000000)*0.35,IF(L7<=300000000,37060000+(L7-150000000)*0.38,IF(L7<=500000000,94060000+(L7-300000000)*0.4,IF(L7<=1000000000,174060000+(L7-500000000)*0.42,384060000+(L7-1000000000)*0.45))))))) -> 8578128 | N7: =MIN(IF(M7<=1300000,M7*0.55,715000+(M7-1300000)*0.3),IF(F7<=33000000,740000,IF(F7<=70000000,MAX(660000,740000-(F7-33000000)*0.008),MAX(500000,660000-(F7-70000000)*0.5)))) -> 500000 | O7: =MAX(0,M7-N7) -> 8078128 | P7: =TRUNC(O7/12,-1) -> 673170 | Q7: =TRUNC(P7*요율기준!$B$12,-1) -> 67310 | R7: =P7+Q7 -> 740480
A8: =급여대장!A8 -> 46113 | B8: 1 | C8: =급여대장!D8 -> 가온누리 | D8: =직원정보!I5 -> 1 | E8: =급여대장!V8 -> 7286600 | F8: =E8*12 -> 87439200 | G8: =MIN(20000000,IF(F8<=5000000,F8*0.7,IF(F8<=15000000,3500000+(F8-5000000)*0.4,IF(F8<=45000000,7500000+(F8-15000000)*0.15,IF(F8<=100000000,12000000+(F8-45000000)*0.05,14750000+(F8-100000000)*0.02))))) -> 14121960 | H8: =F8-G8 -> 73317240 | I8: =D8*요율기준!$B$13 -> 1500000 | J8: ='4대보험'!F8*12 -> 3439800 | K8: =IF(D8=1,3100000+F8*0.04,IF(D8=2,3600000+F8*0.04,5000000+F8*0.07)) -> 6597568 | L8: =MAX(0,H8-I8-J8-K8) -> 61779872 | M8: =IF(L8<=14000000,L8*0.06,IF(L8<=50000000,840000+(L8-14000000)*0.15,IF(L8<=88000000,6240000+(L8-50000000)*0.24,IF(L8<=150000000,15360000+(L8-88000000)*0.35,IF(L8<=300000000,37060000+(L8-150000000)*0.38,IF(L8<=500000000,94060000+(L8-300000000)*0.4,IF(L8<=1000000000,174060000+(L8-500000000)*0.42,384060000+(L8-1000000000)*0.45))))))) -> 9067169.3 | N8: =MIN(IF(M8<=1300000,M8*0.55,715000+(M8-1300000)*0.3),IF(F8<=33000000,740000,IF(F8<=70000000,MAX(660000,740000-(F8-33000000)*0.008),MAX(500000,660000-(F8-70000000)*0.5)))) -> 500000 | O8: =MAX(0,M8-N8) -> 8567169.3 | P8: =TRUNC(O8/12,-1) -> 713930 | Q8: =TRUNC(P8*요율기준!$B$12,-1) -> 71390 | R8: =P8+Q8 -> 785320
A9: =급여대장!A9 -> 46143 | B9: 1 | C9: =급여대장!D9 -> 가온누리 | D9: =직원정보!I5 -> 1 | E9: =급여대장!V9 -> 7100000 | F9: =E9*12 -> 85200000 | G9: =MIN(20000000,IF(F9<=5000000,F9*0.7,IF(F9<=15000000,3500000+(F9-5000000)*0.4,IF(F9<=45000000,7500000+(F9-15000000)*0.15,IF(F9<=100000000,12000000+(F9-45000000)*0.05,14750000+(F9-100000000)*0.02))))) -> 14010000 | H9: =F9-G9 -> 71190000 | I9: =D9*요율기준!$B$13 -> 1500000 | J9: ='4대보험'!F9*12 -> 3439800 | K9: =IF(D9=1,3100000+F9*0.04,IF(D9=2,3600000+F9*0.04,5000000+F9*0.07)) -> 6508000 | L9: =MAX(0,H9-I9-J9-K9) -> 59742200 | M9: =IF(L9<=14000000,L9*0.06,IF(L9<=50000000,840000+(L9-14000000)*0.15,IF(L9<=88000000,6240000+(L9-50000000)*0.24,IF(L9<=150000000,15360000+(L9-88000000)*0.35,IF(L9<=300000000,37060000+(L9-150000000)*0.38,IF(L9<=500000000,94060000+(L9-300000000)*0.4,IF(L9<=1000000000,174060000+(L9-500000000)*0.42,384060000+(L9-1000000000)*0.45))))))) -> 8578128 | N9: =MIN(IF(M9<=1300000,M9*0.55,715000+(M9-1300000)*0.3),IF(F9<=33000000,740000,IF(F9<=70000000,MAX(660000,740000-(F9-33000000)*0.008),MAX(500000,660000-(F9-70000000)*0.5)))) -> 500000 | O9: =MAX(0,M9-N9) -> 8078128 | P9: =TRUNC(O9/12,-1) -> 673170 | Q9: =TRUNC(P9*요율기준!$B$12,-1) -> 67310 | R9: =P9+Q9 -> 740480
A10: =급여대장!A10 -> 46174 | B10: 1 | C10: =급여대장!D10 -> 가온누리 | D10: =직원정보!I5 -> 1 | E10: =급여대장!V10 -> 7286600 | F10: =E10*12 -> 87439200 | G10: =MIN(20000000,IF(F10<=5000000,F10*0.7,IF(F10<=15000000,3500000+(F10-5000000)*0.4,IF(F10<=45000000,7500000+(F10-15000000)*0.15,IF(F10<=100000000,12000000+(F10-45000000)*0.05,14750000+(F10-100000000)*0.02))))) -> 14121960 | H10: =F10-G10 -> 73317240 | I10: =D10*요율기준!$B$13 -> 1500000 | J10: ='4대보험'!F10*12 -> 3439800 | K10: =IF(D10=1,3100000+F10*0.04,IF(D10=2,3600000+F10*0.04,5000000+F10*0.07)) -> 6597568 | L10: =MAX(0,H10-I10-J10-K10) -> 61779872 | M10: =IF(L10<=14000000,L10*0.06,IF(L10<=50000000,840000+(L10-14000000)*0.15,IF(L10<=88000000,6240000+(L10-50000000)*0.24,IF(L10<=150000000,15360000+(L10-88000000)*0.35,IF(L10<=300000000,37060000+(L10-150000000)*0.38,IF(L10<=500000000,94060000+(L10-300000000)*0.4,IF(L10<=1000000000,174060000+(L10-500000000)*0.42,384060000+(L10-1000000000)*0.45))))))) -> 9067169.3 | N10: =MIN(IF(M10<=1300000,M10*0.55,715000+(M10-1300000)*0.3),IF(F10<=33000000,740000,IF(F10<=70000000,MAX(660000,740000-(F10-33000000)*0.008),MAX(500000,660000-(F10-70000000)*0.5)))) -> 500000 | O10: =MAX(0,M10-N10) -> 8567169.3 | P10: =TRUNC(O10/12,-1) -> 713930 | Q10: =TRUNC(P10*요율기준!$B$12,-1) -> 71390 | R10: =P10+Q10 -> 785320
A11: =급여대장!A11 -> 46204 | B11: 1 | C11: =급여대장!D11 -> 가온누리 | D11: =직원정보!I5 -> 1 | E11: =급여대장!V11 -> 7100000 | F11: =E11*12 -> 85200000 | G11: =MIN(20000000,IF(F11<=5000000,F11*0.7,IF(F11<=15000000,3500000+(F11-5000000)*0.4,IF(F11<=45000000,7500000+(F11-15000000)*0.15,IF(F11<=100000000,12000000+(F11-45000000)*0.05,14750000+(F11-100000000)*0.02))))) -> 14010000 | H11: =F11-G11 -> 71190000 | I11: =D11*요율기준!$B$13 -> 1500000 | J11: ='4대보험'!F11*12 -> 3439800 | K11: =IF(D11=1,3100000+F11*0.04,IF(D11=2,3600000+F11*0.04,5000000+F11*0.07)) -> 6508000 | L11: =MAX(0,H11-I11-J11-K11) -> 59742200 | M11: =IF(L11<=14000000,L11*0.06,IF(L11<=50000000,840000+(L11-14000000)*0.15,IF(L11<=88000000,6240000+(L11-50000000)*0.24,IF(L11<=150000000,15360000+(L11-88000000)*0.35,IF(L11<=300000000,37060000+(L11-150000000)*0.38,IF(L11<=500000000,94060000+(L11-300000000)*0.4,IF(L11<=1000000000,174060000+(L11-500000000)*0.42,384060000+(L11-1000000000)*0.45))))))) -> 8578128 | N11: =MIN(IF(M11<=1300000,M11*0.55,715000+(M11-1300000)*0.3),IF(F11<=33000000,740000,IF(F11<=70000000,MAX(660000,740000-(F11-33000000)*0.008),MAX(500000,660000-(F11-70000000)*0.5)))) -> 500000 | O11: =MAX(0,M11-N11) -> 8078128 | P11: =TRUNC(O11/12,-1) -> 673170 | Q11: =TRUNC(P11*요율기준!$B$12,-1) -> 67310 | R11: =P11+Q11 -> 740480
A12: =급여대장!A12 -> 46235 | B12: 1 | C12: =급여대장!D12 -> 가온누리 | D12: =직원정보!I5 -> 1 | E12: =급여대장!V12 -> 7286600 | F12: =E12*12 -> 87439200 | G12: =MIN(20000000,IF(F12<=5000000,F12*0.7,IF(F12<=15000000,3500000+(F12-5000000)*0.4,IF(F12<=45000000,7500000+(F12-15000000)*0.15,IF(F12<=100000000,12000000+(F12-45000000)*0.05,14750000+(F12-100000000)*0.02))))) -> 14121960 | H12: =F12-G12 -> 73317240 | I12: =D12*요율기준!$B$13 -> 1500000 | J12: ='4대보험'!F12*12 -> 3439800 | K12: =IF(D12=1,3100000+F12*0.04,IF(D12=2,3600000+F12*0.04,5000000+F12*0.07)) -> 6597568 | L12: =MAX(0,H12-I12-J12-K12) -> 61779872 | M12: =IF(L12<=14000000,L12*0.06,IF(L12<=50000000,840000+(L12-14000000)*0.15,IF(L12<=88000000,6240000+(L12-50000000)*0.24,IF(L12<=150000000,15360000+(L12-88000000)*0.35,IF(L12<=300000000,37060000+(L12-150000000)*0.38,IF(L12<=500000000,94060000+(L12-300000000)*0.4,IF(L12<=1000000000,174060000+(L12-500000000)*0.42,384060000+(L12-1000000000)*0.45))))))) -> 9067169.3 | N12: =MIN(IF(M12<=1300000,M12*0.55,715000+(M12-1300000)*0.3),IF(F12<=33000000,740000,IF(F12<=70000000,MAX(660000,740000-(F12-33000000)*0.008),MAX(500000,660000-(F12-70000000)*0.5)))) -> 500000 | O12: =MAX(0,M12-N12) -> 8567169.3 | P12: =TRUNC(O12/12,-1) -> 713930 | Q12: =TRUNC(P12*요율기준!$B$12,-1) -> 71390 | R12: =P12+Q12 -> 785320
A13: =급여대장!A13 -> 46266 | B13: 1 | C13: =급여대장!D13 -> 가온누리 | D13: =직원정보!I5 -> 1 | E13: =급여대장!V13 -> 7100000 | F13: =E13*12 -> 85200000 | G13: =MIN(20000000,IF(F13<=5000000,F13*0.7,IF(F13<=15000000,3500000+(F13-5000000)*0.4,IF(F13<=45000000,7500000+(F13-15000000)*0.15,IF(F13<=100000000,12000000+(F13-45000000)*0.05,14750000+(F13-100000000)*0.02))))) -> 14010000 | H13: =F13-G13 -> 71190000 | I13: =D13*요율기준!$B$13 -> 1500000 | J13: ='4대보험'!F13*12 -> 3439800 | K13: =IF(D13=1,3100000+F13*0.04,IF(D13=2,3600000+F13*0.04,5000000+F13*0.07)) -> 6508000 | L13: =MAX(0,H13-I13-J13-K13) -> 59742200 | M13: =IF(L13<=14000000,L13*0.06,IF(L13<=50000000,840000+(L13-14000000)*0.15,IF(L13<=88000000,6240000+(L13-50000000)*0.24,IF(L13<=150000000,15360000+(L13-88000000)*0.35,IF(L13<=300000000,37060000+(L13-150000000)*0.38,IF(L13<=500000000,94060000+(L13-300000000)*0.4,IF(L13<=1000000000,174060000+(L13-500000000)*0.42,384060000+(L13-1000000000)*0.45))))))) -> 8578128 | N13: =MIN(IF(M13<=1300000,M13*0.55,715000+(M13-1300000)*0.3),IF(F13<=33000000,740000,IF(F13<=70000000,MAX(660000,740000-(F13-33000000)*0.008),MAX(500000,660000-(F13-70000000)*0.5)))) -> 500000 | O13: =MAX(0,M13-N13) -> 8078128 | P13: =TRUNC(O13/12,-1) -> 673170 | Q13: =TRUNC(P13*요율기준!$B$12,-1) -> 67310 | R13: =P13+Q13 -> 740480
A14: =급여대장!A14 -> 46296 | B14: 1 | C14: =급여대장!D14 -> 가온누리 | D14: =직원정보!I5 -> 1 | E14: =급여대장!V14 -> 7286600 | F14: =E14*12 -> 87439200 | G14: =MIN(20000000,IF(F14<=5000000,F14*0.7,IF(F14<=15000000,3500000+(F14-5000000)*0.4,IF(F14<=45000000,7500000+(F14-15000000)*0.15,IF(F14<=100000000,12000000+(F14-45000000)*0.05,14750000+(F14-100000000)*0.02))))) -> 14121960 | H14: =F14-G14 -> 73317240 | I14: =D14*요율기준!$B$13 -> 1500000 | J14: ='4대보험'!F14*12 -> 3439800 | K14: =IF(D14=1,3100000+F14*0.04,IF(D14=2,3600000+F14*0.04,5000000+F14*0.07)) -> 6597568 | L14: =MAX(0,H14-I14-J14-K14) -> 61779872 | M14: =IF(L14<=14000000,L14*0.06,IF(L14<=50000000,840000+(L14-14000000)*0.15,IF(L14<=88000000,6240000+(L14-50000000)*0.24,IF(L14<=150000000,15360000+(L14-88000000)*0.35,IF(L14<=300000000,37060000+(L14-150000000)*0.38,IF(L14<=500000000,94060000+(L14-300000000)*0.4,IF(L14<=1000000000,174060000+(L14-500000000)*0.42,384060000+(L14-1000000000)*0.45))))))) -> 9067169.3 | N14: =MIN(IF(M14<=1300000,M14*0.55,715000+(M14-1300000)*0.3),IF(F14<=33000000,740000,IF(F14<=70000000,MAX(660000,740000-(F14-33000000)*0.008),MAX(500000,660000-(F14-70000000)*0.5)))) -> 500000 | O14: =MAX(0,M14-N14) -> 8567169.3 | P14: =TRUNC(O14/12,-1) -> 713930 | Q14: =TRUNC(P14*요율기준!$B$12,-1) -> 71390 | R14: =P14+Q14 -> 785320
A15: =급여대장!A15 -> 46327 | B15: 1 | C15: =급여대장!D15 -> 가온누리 | D15: =직원정보!I5 -> 1 | E15: =급여대장!V15 -> 7100000 | F15: =E15*12 -> 85200000 | G15: =MIN(20000000,IF(F15<=5000000,F15*0.7,IF(F15<=15000000,3500000+(F15-5000000)*0.4,IF(F15<=45000000,7500000+(F15-15000000)*0.15,IF(F15<=100000000,12000000+(F15-45000000)*0.05,14750000+(F15-100000000)*0.02))))) -> 14010000 | H15: =F15-G15 -> 71190000 | I15: =D15*요율기준!$B$13 -> 1500000 | J15: ='4대보험'!F15*12 -> 3439800 | K15: =IF(D15=1,3100000+F15*0.04,IF(D15=2,3600000+F15*0.04,5000000+F15*0.07)) -> 6508000 | L15: =MAX(0,H15-I15-J15-K15) -> 59742200 | M15: =IF(L15<=14000000,L15*0.06,IF(L15<=50000000,840000+(L15-14000000)*0.15,IF(L15<=88000000,6240000+(L15-50000000)*0.24,IF(L15<=150000000,15360000+(L15-88000000)*0.35,IF(L15<=300000000,37060000+(L15-150000000)*0.38,IF(L15<=500000000,94060000+(L15-300000000)*0.4,IF(L15<=1000000000,174060000+(L15-500000000)*0.42,384060000+(L15-1000000000)*0.45))))))) -> 8578128 | N15: =MIN(IF(M15<=1300000,M15*0.55,715000+(M15-1300000)*0.3),IF(F15<=33000000,740000,IF(F15<=70000000,MAX(660000,740000-(F15-33000000)*0.008),MAX(500000,660000-(F15-70000000)*0.5)))) -> 500000 | O15: =MAX(0,M15-N15) -> 8078128 | P15: =TRUNC(O15/12,-1) -> 673170 | Q15: =TRUNC(P15*요율기준!$B$12,-1) -> 67310 | R15: =P15+Q15 -> 740480
A16: =급여대장!A16 -> 46357 | B16: 1 | C16: =급여대장!D16 -> 가온누리 | D16: =직원정보!I5 -> 1 | E16: =급여대장!V16 -> 7286600 | F16: =E16*12 -> 87439200 | G16: =MIN(20000000,IF(F16<=5000000,F16*0.7,IF(F16<=15000000,3500000+(F16-5000000)*0.4,IF(F16<=45000000,7500000+(F16-15000000)*0.15,IF(F16<=100000000,12000000+(F16-45000000)*0.05,14750000+(F16-100000000)*0.02))))) -> 14121960 | H16: =F16-G16 -> 73317240 | I16: =D16*요율기준!$B$13 -> 1500000 | J16: ='4대보험'!F16*12 -> 3439800 | K16: =IF(D16=1,3100000+F16*0.04,IF(D16=2,3600000+F16*0.04,5000000+F16*0.07)) -> 6597568 | L16: =MAX(0,H16-I16-J16-K16) -> 61779872 | M16: =IF(L16<=14000000,L16*0.06,IF(L16<=50000000,840000+(L16-14000000)*0.15,IF(L16<=88000000,6240000+(L16-50000000)*0.24,IF(L16<=150000000,15360000+(L16-88000000)*0.35,IF(L16<=300000000,37060000+(L16-150000000)*0.38,IF(L16<=500000000,94060000+(L16-300000000)*0.4,IF(L16<=1000000000,174060000+(L16-500000000)*0.42,384060000+(L16-1000000000)*0.45))))))) -> 9067169.3 | N16: =MIN(IF(M16<=1300000,M16*0.55,715000+(M16-1300000)*0.3),IF(F16<=33000000,740000,IF(F16<=70000000,MAX(660000,740000-(F16-33000000)*0.008),MAX(500000,660000-(F16-70000000)*0.5)))) -> 500000 | O16: =MAX(0,M16-N16) -> 8567169.3 | P16: =TRUNC(O16/12,-1) -> 713930 | Q16: =TRUNC(P16*요율기준!$B$12,-1) -> 71390 | R16: =P16+Q16 -> 785320
A17: =급여대장!A17 -> 46023 | B17: 2 | C17: =급여대장!D17 -> 나래솔 | D17: =직원정보!I6 -> 1 | E17: =급여대장!V17 -> 5749280 | F17: =E17*12 -> 68991360 | G17: =MIN(20000000,IF(F17<=5000000,F17*0.7,IF(F17<=15000000,3500000+(F17-5000000)*0.4,IF(F17<=45000000,7500000+(F17-15000000)*0.15,IF(F17<=100000000,12000000+(F17-45000000)*0.05,14750000+(F17-100000000)*0.02))))) -> 13199568 | H17: =F17-G17 -> 55791792 | I17: =D17*요율기준!$B$13 -> 1500000 | J17: ='4대보험'!F17*12 -> 3104520 | K17: =IF(D17=1,3100000+F17*0.04,IF(D17=2,3600000+F17*0.04,5000000+F17*0.07)) -> 5859654.4 | L17: =MAX(0,H17-I17-J17-K17) -> 45327618 | M17: =IF(L17<=14000000,L17*0.06,IF(L17<=50000000,840000+(L17-14000000)*0.15,IF(L17<=88000000,6240000+(L17-50000000)*0.24,IF(L17<=150000000,15360000+(L17-88000000)*0.35,IF(L17<=300000000,37060000+(L17-150000000)*0.38,IF(L17<=500000000,94060000+(L17-300000000)*0.4,IF(L17<=1000000000,174060000+(L17-500000000)*0.42,384060000+(L17-1000000000)*0.45))))))) -> 5539142.6 | N17: =MIN(IF(M17<=1300000,M17*0.55,715000+(M17-1300000)*0.3),IF(F17<=33000000,740000,IF(F17<=70000000,MAX(660000,740000-(F17-33000000)*0.008),MAX(500000,660000-(F17-70000000)*0.5)))) -> 660000 | O17: =MAX(0,M17-N17) -> 4879142.6 | P17: =TRUNC(O17/12,-1) -> 406590 | Q17: =TRUNC(P17*요율기준!$B$12,-1) -> 40650 | R17: =P17+Q17 -> 447240
A18: =급여대장!A18 -> 46054 | B18: 2 | C18: =급여대장!D18 -> 나래솔 | D18: =직원정보!I6 -> 1 | E18: =급여대장!V18 -> 5600000 | F18: =E18*12 -> 67200000 | G18: =MIN(20000000,IF(F18<=5000000,F18*0.7,IF(F18<=15000000,3500000+(F18-5000000)*0.4,IF(F18<=45000000,7500000+(F18-15000000)*0.15,IF(F18<=100000000,12000000+(F18-45000000)*0.05,14750000+(F18-100000000)*0.02))))) -> 13110000 | H18: =F18-G18 -> 54090000 | I18: =D18*요율기준!$B$13 -> 1500000 | J18: ='4대보험'!F18*12 -> 3024000 | K18: =IF(D18=1,3100000+F18*0.04,IF(D18=2,3600000+F18*0.04,5000000+F18*0.07)) -> 5788000 | L18: =MAX(0,H18-I18-J18-K18) -> 43778000 | M18: =IF(L18<=14000000,L18*0.06,IF(L18<=50000000,840000+(L18-14000000)*0.15,IF(L18<=88000000,6240000+(L18-50000000)*0.24,IF(L18<=150000000,15360000+(L18-88000000)*0.35,IF(L18<=300000000,37060000+(L18-150000000)*0.38,IF(L18<=500000000,94060000+(L18-300000000)*0.4,IF(L18<=1000000000,174060000+(L18-500000000)*0.42,384060000+(L18-1000000000)*0.45))))))) -> 5306700 | N18: =MIN(IF(M18<=1300000,M18*0.55,715000+(M18-1300000)*0.3),IF(F18<=33000000,740000,IF(F18<=70000000,MAX(660000,740000-(F18-33000000)*0.008),MAX(500000,660000-(F18-70000000)*0.5)))) -> 660000 | O18: =MAX(0,M18-N18) -> 4646700 | P18: =TRUNC(O18/12,-1) -> 387220 | Q18: =TRUNC(P18*요율기준!$B$12,-1) -> 38720 | R18: =P18+Q18 -> 425940
A19: =급여대장!A19 -> 46082 | B19: 2 | C19: =급여대장!D19 -> 나래솔 | D19: =직원정보!I6 -> 1 | E19: =급여대장!V19 -> 5749280 | F19: =E19*12 -> 68991360 | G19: =MIN(20000000,IF(F19<=5000000,F19*0.7,IF(F19<=15000000,3500000+(F19-5000000)*0.4,IF(F19<=45000000,7500000+(F19-15000000)*0.15,IF(F19<=100000000,12000000+(F19-45000000)*0.05,14750000+(F19-100000000)*0.02))))) -> 13199568 | H19: =F19-G19 -> 55791792 | I19: =D19*요율기준!$B$13 -> 1500000 | J19: ='4대보험'!F19*12 -> 3104520 | K19: =IF(D19=1,3100000+F19*0.04,IF(D19=2,3600000+F19*0.04,5000000+F19*0.07)) -> 5859654.4 | L19: =MAX(0,H19-I19-J19-K19) -> 45327618 | M19: =IF(L19<=14000000,L19*0.06,IF(L19<=50000000,840000+(L19-14000000)*0.15,IF(L19<=88000000,6240000+(L19-50000000)*0.24,IF(L19<=150000000,15360000+(L19-88000000)*0.35,IF(L19<=300000000,37060000+(L19-150000000)*0.38,IF(L19<=500000000,94060000+(L19-300000000)*0.4,IF(L19<=1000000000,174060000+(L19-500000000)*0.42,384060000+(L19-1000000000)*0.45))))))) -> 5539142.6 | N19: =MIN(IF(M19<=1300000,M19*0.55,715000+(M19-1300000)*0.3),IF(F19<=33000000,740000,IF(F19<=70000000,MAX(660000,740000-(F19-33000000)*0.008),MAX(500000,660000-(F19-70000000)*0.5)))) -> 660000 | O19: =MAX(0,M19-N19) -> 4879142.6 | P19: =TRUNC(O19/12,-1) -> 406590 | Q19: =TRUNC(P19*요율기준!$B$12,-1) -> 40650 | R19: =P19+Q19 -> 447240
